Workbook
Name ราคา: ราคาขนส่ง!$I$2:$I$3
Name สถานที่: ราคาขนส่ง!$B$3:$B$52

Sheet ผท-3888
A1: สรุปค่าบรรทุกรถร่วมกระจายสินค้าสาขานครสวรรค์
A2: =+รายการหัก!I1 -> รอบวันที่ 1-15 พฤษภาคม 2569 | D2: ทะเบียน | E2: ผท-3888 | I2: =VLOOKUP(E2,Table22[],2,0) -> นายมาโนช ยนตะสุข
A3: =+รายการหัก!B1 -> เงินออกรอบ 5
A4: วันที่ขึ้นของ | B4: ปลายทาง | C4: เลขที่ใบกระจาย | D4: จำนวน/ชิ้น | E4: ค่าขนส่ง | F4: ราคา | G4: เป็นเงิน | H4: พิเศษ | I4: ราคารวม | J4: คงเหลือสุทธิ | K4: หมายเหตุ
A5: 46143 | B5: อ.เมือง จ.พช | C5: JB0326106786 | D5: 425 | E5: ราคาชิ้น | F5: {=IFERROR(INDEX(ราคาขนส่ง!$D$3:$D$102,MATCH(1,IF(ราคาขนส่ง!$B$3:$B$102=$B5,IF(ราคาขนส่ง!$C$3:$C$102=$E5,1)),0)),"")} -> 9.3 | G5: =IFERROR(IF(F5>10,F5,F5*D5),"") -> 3952.5 | I5: =IFERROR(SUM(G5+H5),"") -> 3952.5 | J5: =IFERROR(SUM(H5+I5),"") -> 3952.5
A6: 46144 | B6: อ.เมือง จ.ชัยนาท | C6: JB0326106820 | D6: 123 | E6: ราคาเหมา | F6: {=IFERROR(INDEX(ราคาขนส่ง!$D$3:$D$102,MATCH(1,IF(ราคาขนส่ง!$B$3:$B$102=$B6,IF(ราคาขนส่ง!$C$3:$C$102=$E6,1)),0)),"")} -> 1300 | G6: =IFERROR(IF(F6>10,F6,F6*D6),"") -> 1300 | I6: =IFERROR(SUM(G6+H6),"") -> 1300 | J6: =IFERROR(SUM(H6+I6),"") -> 1300
A7: 46144 | B7: อ.เมือง จ.ชัยนาท | C7: JB0326106821 | D7: 327 | E7: ราคาชิ้น | F7: {=IFERROR(INDEX(ราคาขนส่ง!$D$3:$D$102,MATCH(1,IF(ราคาขนส่ง!$B$3:$B$102=$B7,IF(ราคาขนส่ง!$C$3:$C$102=$E7,1)),0)),"")} -> 5.6 | G7: =IFERROR(IF(F7>10,F7,F7*D7),"") -> 1831.2 | I7: =IFERROR(SUM(G7+H7),"") -> 1831.2 | J7: =IFERROR(SUM(H7+I7),"") -> 1831.2
A8: 46145 | B8: อ.โพทะเล จ.พิจิตร | C8: JB0326106825 | D8: 171 | E8: ราคาเหมา | F8: {=IFERROR(INDEX(ราคาขนส่ง!$D$3:$D$102,MATCH(1,IF(ราคาขนส่ง!$B$3:$B$102=$B8,IF(ราคาขนส่ง!$C$3:$C$102=$E8,1)),0)),"")} -> 1350 | G8: =IFERROR(IF(F8>10,F8,F8*D8),"") -> 1350 | I8: =IFERROR(SUM(G8+H8),"") -> 1350 | J8: =IFERROR(SUM(H8+I8),"") -> 1350
A9: 46146 | B9: อ.เมือง จ.นว | C9: JB0326106839 | D9: 390 | E9: ราคาชิ้น | F9: {=IFERROR(INDEX(ราคาขนส่ง!$D$3:$D$102,MATCH(1,IF(ราคาขนส่ง!$B$3:$B$102=$B9,IF(ราคาขนส่ง!$C$3:$C$102=$E9,1)),0)),"")} -> 3 | G9: =IFERROR(IF(F9>10,F9,F9*D9),"") -> 1170 | I9: =IFERROR(SUM(G9+H9),"") -> 1170 | J9: =IFERROR(SUM(H9+I9),"") -> 1170
A10: 46146 | B10: อ.เมือง จ.พิจิตร | C10: JB0326106853 | D10: 155 | E10: ราคาเหมา | F10: {=IFERROR(INDEX(ราคาขนส่ง!$D$3:$D$102,MATCH(1,IF(ราคาขนส่ง!$B$3:$B$102=$B10,IF(ราคาขนส่ง!$C$3:$C$102=$E10,1)),0)),"")} -> 1650 | G10: =IFERROR(IF(F10>10,F10,F10*D10),"") -> 1650 | I10: =IFERROR(SUM(G10+H10),"") -> 1650 | J10: =IFERROR(SUM(H10+I10),"") -> 1650
A11: 46147 | B11: อ.เมือง จ.พิจิตร | C11: JB0326106852 | D11: 150 | E11: ราคาเหมา | F11: {=IFERROR(INDEX(ราคาขนส่ง!$D$3:$D$102,MATCH(1,IF(ราคาขนส่ง!$B$3:$B$102=$B11,IF(ราคาขนส่ง!$C$3:$C$102=$E11,1)),0)),"")} -> 1650 | G11: =IFERROR(IF(F11>10,F11,F11*D11),"") -> 1650 | I11: =IFERROR(SUM(G11+H11),"") -> 1650 | J11: =IFERROR(SUM(H11+I11),"") -> 1650
A12: 46148 | B12: อ.หันคา จ.ชัยนาท | C12: JB0326106873 | D12: 132 | E12: ราคาเหมา | F12: {=IFERROR(INDEX(ราคาขนส่ง!$D$3:$D$102,MATCH(1,IF(ราคาขนส่ง!$B$3:$B$102=$B12,IF(ราคาขนส่ง!$C$3:$C$102=$E12,1)),0)),"")} -> 1700 | G12: =IFERROR(IF(F12>10,F12,F12*D12),"") -> 1700 | I12: =IFERROR(SUM(G12+H12),"") -> 1700 | J12: =IFERROR(SUM(H12+I12),"") -> 1700
A13: 46148 | B13: อ.เมือง จ.พิจิตร | C13: JB0326106854 | D13: 144 | E13: ราคาเหมา | F13: {=IFERROR(INDEX(ราคาขนส่ง!$D$3:$D$102,MATCH(1,IF(ราคาขนส่ง!$B$3:$B$102=$B13,IF(ราคาขนส่ง!$C$3:$C$102=$E13,1)),0)),"")} -> 1650 | G13: =IFERROR(IF(F13>10,F13,F13*D13),"") -> 1650 | I13: =IFERROR(SUM(G13+H13),"") -> 1650 | J13: =IFERROR(SUM(H13+I13),"") -> 1650
A14: 46149 | B14: อ.เมือง จ.พิจิตร | C14: JB0326106871 | D14: 137 | E14: ราคาเหมา | F14: {=IFERROR(INDEX(ราคาขนส่ง!$D$3:$D$102,MATCH(1,IF(ราคาขนส่ง!$B$3:$B$102=$B14,IF(ราคาขนส่ง!$C$3:$C$102=$E14,1)),0)),"")} -> 1650 | G14: =IFERROR(IF(F14>10,F14,F14*D14),"") -> 1650 | I14: =IFERROR(SUM(G14+H14),"") -> 1650 | J14: =IFERROR(SUM(H14+I14),"") -> 1650
A15: 46150 | B15: อ.เมือง จ.อุทัย | C15: JB0326106927 | D15: 82 | E15: ราคาเหมา | F15: {=IFERROR(INDEX(ราคาขนส่ง!$D$3:$D$102,MATCH(1,IF(ราคาขนส่ง!$B$3:$B$102=$B15,IF(ราคาขนส่ง!$C$3:$C$102=$E15,1)),0)),"")} -> 1300 | G15: =IFERROR(IF(F15>10,F15,F15*D15),"") -> 1300 | I15: =IFERROR(SUM(G15+H15),"") -> 1300 | J15: =IFERROR(SUM(H15+I15),"") -> 1300
A16: 46150 | B16: อ.เมือง จ.พช | C16: JB0326106907 | D16: 142 | E16: ราคาเหมา | F16: {=IFERROR(INDEX(ราคาขนส่ง!$D$3:$D$102,MATCH(1,IF(ราคาขนส่ง!$B$3:$B$102=$B16,IF(ราคาขนส่ง!$C$3:$C$102=$E16,1)),0)),"")} -> 2500 | G16: =IFERROR(IF(F16>10,F16,F16*D16),"") -> 2500 | I16: =IFERROR(SUM(G16+H16),"") -> 2500 | J16: =IFERROR(SUM(H16+I16),"") -> 2500 | K16: มีหาร
A17: 46151 | B17: อ.เมือง จ.อุทัย | C17: JB0326106926 | D17: 148 | E17: ราคาเหมา | F17: {=IFERROR(INDEX(ราคาขนส่ง!$D$3:$D$102,MATCH(1,IF(ราคาขนส่ง!$B$3:$B$102=$B17,IF(ราคาขนส่ง!$C$3:$C$102=$E17,1)),0)),"")} -> 1300 | G17: =IFERROR(IF(F17>10,F17,F17*D17),"") -> 1300 | I17: =IFERROR(SUM(G17+H17),"") -> 1300 | J17: =IFERROR(SUM(H17+I17),"") -> 1300
A18: 46152 | B18: อ.เมือง จ.พิจิตร | C18: JB0326106963 | D18: 168 | E18: ราคาเหมา | F18: {=IFERROR(INDEX(ราคาขนส่ง!$D$3:$D$102,MATCH(1,IF(ราคาขนส่ง!$B$3:$B$102=$B18,IF(ราคาขนส่ง!$C$3:$C$102=$E18,1)),0)),"")} -> 1650 | G18: =IFERROR(IF(F18>10,F18,F18*D18),"") -> 1650 | I18: =IFERROR(SUM(G18+H18),"") -> 1650 | J18: =IFERROR(SUM(H18+I18),"") -> 1650
A19: 46153 | B19: อ.ตาคลี จ.นว | C19: JB0326106944 | D19: 397 | E19: ราคาชิ้น | F19: {=IFERROR(INDEX(ราคาขนส่ง!$D$3:$D$102,MATCH(1,IF(ราคาขนส่ง!$B$3:$B$102=$B19,IF(ราคาขนส่ง!$C$3:$C$102=$E19,1)),0)),"")} -> 5.6 | G19: =IFERROR(IF(F19>10,F19,F19*D19),"") -> 2223.2 | I19: =IFERROR(SUM(G19+H19),"") -> 2223.2 | J19: =IFERROR(SUM(H19+I19),"") -> 2223.2
A20: 46153 | B20: อ.เมือง จ.นว | C20: JB0326106964 | D20: 140 | E20: ราคาชิ้น | F20: {=IFERROR(INDEX(ราคาขนส่ง!$D$3:$D$102,MATCH(1,IF(ราคาขนส่ง!$B$3:$B$102=$B20,IF(ราคาขนส่ง!$C$3:$C$102=$E20,1)),0)),"")} -> 3 | G20: =IFERROR(IF(F20>10,F20,F20*D20),"") -> 420 | I20: =IFERROR(SUM(G20+H20),"") -> 420 | J20: =IFERROR(SUM(H20+I20),"") -> 420
A21: 46154 | B21: อ.สรรพยา จ.ชัยนาท | C21: JB0326106972 | D21: 209 | E21: ราคาเหมา | F21: {=IFERROR(INDEX(ราคาขนส่ง!$D$3:$D$102,MATCH(1,IF(ราคาขนส่ง!$B$3:$B$102=$B21,IF(ราคาขนส่ง!$C$3:$C$102=$E21,1)),0)),"")} -> 1300 | G21: =IFERROR(IF(F21>10,F21,F21*D21),"") -> 1300 | I21: =IFERROR(SUM(G21+H21),"") -> 1300 | J21: =IFERROR(SUM(H21+I21),"") -> 1300
A22: 46065 | B22: อ.สรรพยา จ.ชัยนาท | C22: JB0326106973 | D22: 210 | E22: ราคาเหมา | F22: {=IFERROR(INDEX(ราคาขนส่ง!$D$3:$D$102,MATCH(1,IF(ราคาขนส่ง!$B$3:$B$102=$B22,IF(ราคาขนส่ง!$C$3:$C$102=$E22,1)),0)),"")} -> 1300 | G22: =IFERROR(IF(F22>10,F22,F22*D22),"") -> 1300 | I22: =IFERROR(SUM(G22+H22),"") -> 1300 | J22: =IFERROR(SUM(H22+I22),"") -> 1300
A23: 46155 | B23: อ.เมือง จ.นว | C23: JB0326106991 | D23: 228 | E23: ราคาชิ้น | F23: {=IFERROR(INDEX(ราคาขนส่ง!$D$3:$D$102,MATCH(1,IF(ราคาขนส่ง!$B$3:$B$102=$B23,IF(ราคาขนส่ง!$C$3:$C$102=$E23,1)),0)),"")} -> 3 | G23: =IFERROR(IF(F23>10,F23,F23*D23),"") -> 684 | I23: =IFERROR(SUM(G23+H23),"") -> 684 | J23: =IFERROR(SUM(H23+I23),"") -> 684
A24: 46155 | B24: อ.เมือง จ.พช | C24: JB0326107006 | D24: 176 | E24: ราคาเหมา | F24: {=IFERROR(INDEX(ราคาขนส่ง!$D$3:$D$102,MATCH(1,IF(ราคาขนส่ง!$B$3:$B$102=$B24,IF(ราคาขนส่ง!$C$3:$C$102=$E24,1)),0)),"")} -> 2500 | G24: =IFERROR(IF(F24>10,F24,F24*D24),"") -> 2500 | I24: =IFERROR(SUM(G24+H24),"") -> 2500 | J24: =IFERROR(SUM(H24+I24),"") -> 2500
A25: 46156 | B25: อ.เมือง จ.พช | C25: JB0326107004 | D25: 481 | E25: ราคาชิ้น | F25: {=IFERROR(INDEX(ราคาขนส่ง!$D$3:$D$102,MATCH(1,IF(ราคาขนส่ง!$B$3:$B$102=$B25,IF(ราคาขนส่ง!$C$3:$C$102=$E25,1)),0)),"")} -> 9.3 | G25: =IFERROR(IF(F25>10,F25,F25*D25),"") -> 4473.3 | I25: =IFERROR(SUM(G25+H25),"") -> 4473.3 | J25: =IFERROR(SUM(H25+I25),"") -> 4473.3
A26: 46157 | B26: อ.เมือง จ.พิจิตร | C26: JB0326107025 | D26: 140 | E26: ราคาเหมา | F26: {=IFERROR(INDEX(ราคาขนส่ง!$D$3:$D$102,MATCH(1,IF(ราคาขนส่ง!$B$3:$B$102=$B26,IF(ราคาขนส่ง!$C$3:$C$102=$E26,1)),0)),"")} -> 1650 | G26: =IFERROR(IF(F26>10,F26,F26*D26),"") -> 1650 | I26: =IFERROR(SUM(G26+H26),"") -> 1650 | J26: =IFERROR(SUM(H26+I26),"") -> 1650
E27: ราคาชิ้น | F27: {=IFERROR(INDEX(ราคาขนส่ง!$D$3:$D$102,MATCH(1,IF(ราคาขนส่ง!$B$3:$B$102=$B27,IF(ราคาขนส่ง!$C$3:$C$102=$E27,1)),0)),"")} | G27: =IFERROR(IF(F27>10,F27,F27*D27),"") | I27: =IFERROR(SUM(G27+H27),"") | J27: =IFERROR(SUM(H27+I27),"")
B28: ยอดรวม | D28: =SUM(D5:D27) -> 4675 | I28: =SUM(I5:I27) -> 39204.2 | J28: =SUM(J5:J27) -> 39204.2
A29: สรุป
B30: รายได้ทั้งหมด | C30: =J28 -> 39204.2 | D30: บาท
B31: หัก 1 % | C31: =SUM(C30/100) -> 392.042 | D31: บาท
B32: หักค่าน้ำมัน | C32: =+Table456782[[#Totals],[เป็นจำนวนเงิน(บาท)]] -> 0 | D32: บาท
B33: =+รายการหัก!C2 -> ค่าอัพเดทบิล | C33: =+รายการหัก!C4 -> 0 | D33: บาท
B34: =+รายการหัก!D2 -> หักค่าโทรศัพท์ | C34: =+รายการหัก!D4 -> 0 | D34: บาท
B35: =+รายการหัก!E2 -> หักค่าGPS | C35: =+รายการหัก!E4 -> 0 | D35: บาท | E35: =+รายการหัก!F4 -> 0
B36: =+รายการหัก!G2 -> หักค่ายืมเงิน | C36: =+รายการหัก!G4 -> 0 | D36: บาท | E36: =+รายการหัก!H4 -> 0
B37: =+รายการหัก!I2 -> หักค่าสัญญาณGPS รายปี | C37: =+รายการหัก!I4 -> 0 | D37: บาท | E37: =+รายการหัก!J4 -> 0
B38: =+รายการหัก!K2 -> หักค่าประกัน | C38: =+รายการหัก!K4 -> 0 | D38: บาท | E38: =+รายการหัก!L4 -> 0
B39: รวมรับสุทธิ | C39: =SUM(C30-C31-C32+C33-C34-C35-C36-C37-C38) -> 38812.158 | D39: บาท
B41: ได้รับเอกสารแล้ว กรุณาตรวจสอบด้วยค่ะ ขอบคุณค่ะ

Sheet ผท-3888(2)
A1: สรุปค่าบรรทุกรถร่วมกระจายสินค้าสาขานครสวรรค์
A2: =+รายการหัก!I1 -> รอบวันที่ 1-15 พฤษภาคม 2569 | C2: =+'ผท-3888'!E2 -> ผท-3888 | D2: =+'ผท-3888'!I2 -> นายมาโนช ยนตะสุข
A4: ลำดับที่ | B4: ว.ด.ป. | C4: ใบสั่งเติมน้ำมัน | D4: เป็นจำนวนเงิน(บาท)
A13: ผลรวม | D13: =SUBTOTAL(109,Table456782[เป็นจำนวนเงิน(บาท)]) -> 0

Sheet ผท-6937
A1: สรุปค่าบรรทุกรถร่วมกระจายสินค้าสาขานครสวรรค์
A2: =+รายการหัก!I1 -> รอบวันที่ 1-15 พฤษภาคม 2569 | D2: ทะเบียน | E2: ผท-6937 | I2: =VLOOKUP(E2,Table22[],2,0) -> นายธนโชติ แสงกำแพง
A3: =+รายการหัก!B1 -> เงินออกรอบ 5
A4: วันที่ขึ้นของ | B4: ปลายทาง | C4: เลขที่ใบกระจาย | D4: จำนวน/ชิ้น | E4: ค่าขนส่ง | F4: ราคา | G4: เป็นเงิน | H4: พิเศษ | I4: ราคารวม | J4: คงเหลือสุทธิ | K4: หมายเหตุ
A5: 46143 | B5: อ.เมือง จ.พิจิตร | C5: JB0326106806 | D5: 134 | E5: ราคาเหมา | F5: {=IFERROR(INDEX(ราคาขนส่ง!$D$3:$D$102,MATCH(1,IF(ราคาขนส่ง!$B$3:$B$102=$B5,IF(ราคาขนส่ง!$C$3:$C$102=$E5,1)),0)),"")} -> 1650 | G5: =IFERROR(IF(F5>10,F5,F5*D5),"") -> 1650 | I5: =IFERROR(SUM(G5+H5),"") -> 1650 | J5: =IFERROR(SUM(H5+I5),"") -> 1650
A6: 46144 | B6: อ.เมือง จ.พช | C6: JB0326106816 | D6: 433 | E6: ราคาชิ้น | F6: {=IFERROR(INDEX(ราคาขนส่ง!$D$3:$D$102,MATCH(1,IF(ราคาขนส่ง!$B$3:$B$102=$B6,IF(ราคาขนส่ง!$C$3:$C$102=$E6,1)),0)),"")} -> 9.3 | G6: =IFERROR(IF(F6>10,F6,F6*D6),"") -> 4026.9 | I6: =IFERROR(SUM(G6+H6),"") -> 4026.9 | J6: =IFERROR(SUM(H6+I6),"") -> 4026.9
A7: 46146 | B7: อ.เมือง จ.พช | C7: JB0326106831 | D7: 194 | E7: ราคาเหมา | F7: {=IFERROR(INDEX(ราคาขนส่ง!$D$3:$D$102,MATCH(1,IF(ราคาขนส่ง!$B$3:$B$102=$B7,IF(ราคาขนส่ง!$C$3:$C$102=$E7,1)),0)),"")} -> 2500 | G7: =IFERROR(IF(F7>10,F7,F7*D7),"") -> 2500 | I7: =IFERROR(SUM(G7+H7),"") -> 2500 | J7: =IFERROR(SUM(H7+I7),"") -> 2500
A8: 46147 | B8: อ.เมือง จ.พช | C8: JB0326106826 | D8: 190 | E8: ราคาเหมา | F8: {=IFERROR(INDEX(ราคาขนส่ง!$D$3:$D$102,MATCH(1,IF(ราคาขนส่ง!$B$3:$B$102=$B8,IF(ราคาขนส่ง!$C$3:$C$102=$E8,1)),0)),"")} -> 2500 | G8: =IFERROR(IF(F8>10,F8,F8*D8),"") -> 2500 | I8: =IFERROR(SUM(G8+H8),"") -> 2500 | J8: =IFERROR(SUM(H8+I8),"") -> 2500
A9: 46148 | B9: อ.โพทะเล จ.พิจิตร | C9: JB0326106873 | D9: 146 | E9: ราคาเหมา | F9: {=IFERROR(INDEX(ราคาขนส่ง!$D$3:$D$102,MATCH(1,IF(ราคาขนส่ง!$B$3:$B$102=$B9,IF(ราคาขนส่ง!$C$3:$C$102=$E9,1)),0)),"")} -> 1350 | G9: =IFERROR(IF(F9>10,F9,F9*D9),"") -> 1350 | I9: =IFERROR(SUM(G9+H9),"") -> 1350 | J9: =IFERROR(SUM(H9+I9),"") -> 1350
A10: 46149 | B10: อ.เมือง จ.พช | C10: JB0326106870 | D10: 217 | E10: ราคาเหมา | F10: {=IFERROR(INDEX(ราคาขนส่ง!$D$3:$D$102,MATCH(1,IF(ราคาขนส่ง!$B$3:$B$102=$B10,IF(ราคาขนส่ง!$C$3:$C$102=$E10,1)),0)),"")} -> 2500 | G10: =IFERROR(IF(F10>10,F10,F10*D10),"") -> 2500 | I10: =IFERROR(SUM(G10+H10),"") -> 2500 | J10: =IFERROR(SUM(H10+I10),"") -> 2500
A11: 46150 | B11: อ.เมือง จ.พช | C11: JB0326106880 | D11: 193 | E11: ราคาเหมา | F11: {=IFERROR(INDEX(ราคาขนส่ง!$D$3:$D$102,MATCH(1,IF(ราคาขนส่ง!$B$3:$B$102=$B11,IF(ราคาขนส่ง!$C$3:$C$102=$E11,1)),0)),"")} -> 2500 | G11: =IFERROR(IF(F11>10,F11,F11*D11),"") -> 2500 | I11: =IFERROR(SUM(G11+H11),"") -> 2500 | J11: =IFERROR(SUM(H11+I11),"") -> 2500
A12: 46150 | B12: อ.เมือง จ.นว | C12: JB0326106909 | D12: 273 | E12: ราคาชิ้น | F12: {=IFERROR(INDEX(ราคาขนส่ง!$D$3:$D$102,MATCH(1,IF(ราคาขนส่ง!$B$3:$B$102=$B12,IF(ราคาขนส่ง!$C$3:$C$102=$E12,1)),0)),"")} -> 3 | G12: =IFERROR(IF(F12>10,F12,F12*D12),"") -> 819 | I12: =IFERROR(SUM(G12+H12),"") -> 819 | J12: =IFERROR(SUM(H12+I12),"") -> 819
A13: 46151 | B13: อ.ตะพานหิน จ.พิจิตร | C13: JB0326106931 | D13: 150 | E13: ราคาเหมา | F13: {=IFERROR(INDEX(ราคาขนส่ง!$D$3:$D$102,MATCH(1,IF(ราคาขนส่ง!$B$3:$B$102=$B13,IF(ราคาขนส่ง!$C$3:$C$102=$E13,1)),0)),"")} -> 1650 | G13: =IFERROR(IF(F13>10,F13,F13*D13),"") -> 1650 | I13: =IFERROR(SUM(G13+H13),"") -> 1650 | J13: =IFERROR(SUM(H13+I13),"") -> 1650
A14: 46153 | B14: อ.เมือง จ.นว | C14: JB0326106932 | D14: 110 | E14: ราคาชิ้น | F14: {=IFERROR(INDEX(ราคาขนส่ง!$D$3:$D$102,MATCH(1,IF(ราคาขนส่ง!$B$3:$B$102=$B14,IF(ราคาขนส่ง!$C$3:$C$102=$E14,1)),0)),"")} -> 3 | G14: =IFERROR(IF(F14>10,F14,F14*D14),"") -> 330 | I14: =IFERROR(SUM(G14+H14),"") -> 330 | J14: =IFERROR(SUM(H14+I14),"") -> 330
A15: 46154 | B15: อ.เมือง จ.พช | C15: JB0326106981 | D15: 162 | E15: ราคาเหมา | F15: {=IFERROR(INDEX(ราคาขนส่ง!$D$3:$D$102,MATCH(1,IF(ราคาขนส่ง!$B$3:$B$102=$B15,IF(ราคาขนส่ง!$C$3:$C$102=$E15,1)),0)),"")} -> 2500 | G15: =IFERROR(IF(F15>10,F15,F15*D15),"") -> 2500 | I15: =IFERROR(SUM(G15+H15),"") -> 2500 | J15: =IFERROR(SUM(H15+I15),"") -> 2500
A16: 46155 | B16: อ.ตากฟ้า จ.นว | C16: JB0326106986 | D16: 177 | E16: ราคาเหมา | F16: {=IFERROR(INDEX(ราคาขนส่ง!$D$3:$D$102,MATCH(1,IF(ราคาขนส่ง!$B$3:$B$102=$B16,IF(ราคาขนส่ง!$C$3:$C$102=$E16,1)),0)),"")} -> 1300 | G16: =IFERROR(IF(F16>10,F16,F16*D16),"") -> 1300 | I16: =IFERROR(SUM(G16+H16),"") -> 1300 | J16: =IFERROR(SUM(H16+I16),"") -> 1300
... A18: 46157 | B18: อ.เมือง จ.พช | C18: JB0326107033 | D18: 139 | E18: ราคาเหมา | F18: {=IFERROR(INDEX(ราคาขนส่ง!$D$3:$D$102,MATCH(1,IF(ราคาขนส่ง!$B$3:$B$102=$B18,IF(ราคาขนส่ง!$C$3:$C$102=$E18,1)),0)),"")} -> 2500 | G18: =IFERROR(IF(F18>10,F18,F18*D18),"") -> 2500 | I18: =IFERROR(SUM(G18+H18),"") -> 2500 | J18: =IFERROR(SUM(H18+I18),"") -> 2500
E19: ราคาชิ้น | F19: {=IFERROR(INDEX(ราคาขนส่ง!$D$3:$D$102,MATCH(1,IF(ราคาขนส่ง!$B$3:$B$102=$B19,IF(ราคาขนส่ง!$C$3:$C$102=$E19,1)),0)),"")} | G19: =IFERROR(IF(F19>10,F19,F19*D19),"") | I19: =IFERROR(SUM(G19+H19),"") | J19: =IFERROR(SUM(H19+I19),"")
B20: ยอดรวม | D20: =SUM(D5:D19) -> 2684 | I20: =SUM(I5:I19) -> 28625.9 | J20: =SUM(J5:J19) -> 28625.9
A21: สรุป
B22: รายได้ทั้งหมด | C22: =J20 -> 28625.9 | D22: บาท
B23: หัก 1 % | C23: =SUM(C22/100) -> 286.259 | D23: บาท
B24: หักค่าน้ำมัน | C24: =+Table45678[[#Totals],[เป็นจำนวนเงิน(บาท)]] -> 12500 | D24: บาท
B25: =+รายการหัก!C2 -> ค่าอัพเดทบิล | C25: =+รายการหัก!C6 -> 0 | D25: บาท
B26: =+รายการหัก!D2 -> หักค่าโทรศัพท์ | C26: =+รายการหัก!D6 -> 0 | D26: บาท
B27: =+รายการหัก!E2 -> หักค่าGPS | C27: =+รายการหัก!E6 -> 0 | D27: บาท | E27: =+รายการหัก!F6 -> 0
B28: =+รายการหัก!G2 -> หักค่ายืมเงิน | C28: =+รายการหัก!G6 -> 0 | D28: บาท | E28: =+รายการหัก!H6 -> 0
B29: =+รายการหัก!I2 -> หักค่าสัญญาณGPS รายปี | C29: =+รายการหัก!I6 -> 0 | D29: บาท | E29: =+รายการหัก!J6 -> 0
B30: =+รายการหัก!K2 -> หักค่าประกัน | C30: =+รายการหัก!K6 -> 0 | D30: บาท | E30: =+รายการหัก!L6 -> 0
B31: รวมรับสุทธิ | C31: =SUM(C22-C23-C24+C25-C26-C27-C28-C29-C30) -> 15839.641 | D31: บาท
B33: ได้รับเอกสารแล้ว กรุณาตรวจสอบด้วยค่ะ ขอบคุณค่ะ

Sheet ผท-6937(2)
A1: สรุปค่าบรรทุกรถร่วมกระจายสินค้าสาขานครสวรรค์
A2: =+รายการหัก!I1 -> รอบวันที่ 1-15 พฤษภาคม 2569 | C2: =+'ผท-6937'!E2 -> ผท-6937 | D2: =+'ผท-6937'!I2 -> นายธนโชติ แสงกำแพง
A4: ลำดับที่ | B4: ว.ด.ป. | C4: ใบสั่งเติมน้ำมัน | D4: เป็นจำนวนเงิน(บาท)
A5: 1 | B5: 46143 | C5: 2996 | D5: 1500
A6: 2 | B6: 46146 | C6: 2997 | D6: 1500
A7: 3 | B7: 46147 | C7: 2998 | D7: 1000
A8: 4 | B8: 46148 | C8: 2999 | D8: 1500
A9: 5 | B9: 46150 | C9: 3000 | D9: 1000
A10: 6 | B10: 46151 | C10: 3451 | D10: 1000
A11: 7 | B11: 46153 | C11: 3452 | D11: 1000
A12: 8 | B12: 46154 | C12: 3453 | D12: 1000
A13: 9 | B13: 46155 | C13: 3454 | D13: 1000
A14: 10 | B14: 46156 | C14: 3455 | D14: 2000
A15: ผลรวม | D15: =SUBTOTAL(109,Table45678[เป็นจำนวนเงิน(บาท)]) -> 12500

Sheet ผจ-5663
A2: =+รายการหัก!I1 -> รอบวันที่ 1-15 พฤษภาคม 2569 | D2: ทะเบียน | E2: ผจ-5663 | I2: =VLOOKUP(E2,Table22[],2,0) -> นายภักดี วัฒนพรหม
A3: =+รายการหัก!B1 -> เงินออกรอบ 5
A4: วันที่ขึ้นของ | B4: ปลายทาง | C4: เลขที่ใบกระจาย | D4: จำนวน/ชิ้น | E4: ค่าขนส่ง | F4: ราคา | G4: เป็นเงิน | H4: พิเศษ | I4: ราคารวม | J4: คงเหลือสุทธิ | K4: หมายเหตุ
A5: 46146 | B5: อ.เมือง จ.นว | C5: JB0326106834 | D5: 150 | E5: ราคาชิ้น | F5: {=IFERROR(INDEX(ราคาขนส่ง!$D$3:$D$102,MATCH(1,IF(ราคาขนส่ง!$B$3:$B$102=$B5,IF(ราคาขนส่ง!$C$3:$C$102=$E5,1)),0)),"")} -> 3 | G5: =IFERROR(IF(F5>10,F5,F5*D5),"") -> 450 | I5: =IFERROR(SUM(G5+H5),"") -> 450 | J5: =IFERROR(SUM(H5+I5),"") -> 450 | O5: จ่าย 700
A6: 46146 | B6: อ.เมือง จ.นว | C6: JB0326106838 | D6: 248 | E6: ราคาชิ้น | F6: {=IFERROR(INDEX(ราคาขนส่ง!$D$3:$D$102,MATCH(1,IF(ราคาขนส่ง!$B$3:$B$102=$B6,IF(ราคาขนส่ง!$C$3:$C$102=$E6,1)),0)),"")} -> 3 | G6: =IFERROR(IF(F6>10,F6,F6*D6),"") -> 744 | I6: =IFERROR(SUM(G6+H6),"") -> 744 | J6: =IFERROR(SUM(H6+I6),"") -> 744
A7: 46147 | B7: อ.ตาคลี จ.นว | C7: JB0326106861 | D7: 146 | E7: ราคาเหมา | F7: {=IFERROR(INDEX(ราคาขนส่ง!$D$3:$D$102,MATCH(1,IF(ราคาขนส่ง!$B$3:$B$102=$B7,IF(ราคาขนส่ง!$C$3:$C$102=$E7,1)),0)),"")} -> 1300 | G7: =IFERROR(IF(F7>10,F7,F7*D7),"") -> 1300 | I7: =IFERROR(SUM(G7+H7),"") -> 1300 | J7: =IFERROR(SUM(H7+I7),"") -> 1300
A8: 46148 | B8: อ.ตาคลี จ.นว | C8: JB0326106863 | D8: 165 | E8: ราคาเหมา | F8: {=IFERROR(INDEX(ราคาขนส่ง!$D$3:$D$102,MATCH(1,IF(ราคาขนส่ง!$B$3:$B$102=$B8,IF(ราคาขนส่ง!$C$3:$C$102=$E8,1)),0)),"")} -> 1300 | G8: =IFERROR(IF(F8>10,F8,F8*D8),"") -> 1300 | I8: =IFERROR(SUM(G8+H8),"") -> 1300 | J8: =IFERROR(SUM(H8+I8),"") -> 1300
A9: 46149 | B9: อ.เมือง จ.พิจิตร | C9: JB0326106890 | D9: 169 | E9: ราคาเหมา | F9: {=IFERROR(INDEX(ราคาขนส่ง!$D$3:$D$102,MATCH(1,IF(ราคาขนส่ง!$B$3:$B$102=$B9,IF(ราคาขนส่ง!$C$3:$C$102=$E9,1)),0)),"")} -> 1650 | G9: =IFERROR(IF(F9>10,F9,F9*D9),"") -> 1650 | I9: =IFERROR(SUM(G9+H9),"") -> 1650 | J9: =IFERROR(SUM(H9+I9),"") -> 1650
A10: 46150 | B10: อ.เมือง จ.พิจิตร | C10: JB0326106911 | D10: 145 | E10: ราคาเหมา | F10: {=IFERROR(INDEX(ราคาขนส่ง!$D$3:$D$102,MATCH(1,IF(ราคาขนส่ง!$B$3:$B$102=$B10,IF(ราคาขนส่ง!$C$3:$C$102=$E10,1)),0)),"")} -> 1650 | G10: =IFERROR(IF(F10>10,F10,F10*D10),"") -> 1650 | I10: =IFERROR(SUM(G10+H10),"") -> 1650 | J10: =IFERROR(SUM(H10+I10),"") -> 1650
A11: 46151 | B11: อ.เมือง จ.ชัยนาท | C11: JB0326106925 | D11: 121 | E11: ราคาเหมา | F11: {=IFERROR(INDEX(ราคาขนส่ง!$D$3:$D$102,MATCH(1,IF(ราคาขนส่ง!$B$3:$B$102=$B11,IF(ราคาขนส่ง!$C$3:$C$102=$E11,1)),0)),"")} -> 1300 | G11: =IFERROR(IF(F11>10,F11,F11*D11),"") -> 1300 | I11: =IFERROR(SUM(G11+H11),"") -> 1300 | J11: =IFERROR(SUM(H11+I11),"") -> 1300
A12: 46153 | B12: อ.เมือง จ.นว | C12: JB0326106947 | D12: 102 | E12: ราคาเหมา | F12: {=IFERROR(INDEX(ราคาขนส่ง!$D$3:$D$102,MATCH(1,IF(ราคาขนส่ง!$B$3:$B$102=$B12,IF(ราคาขนส่ง!$C$3:$C$102=$E12,1)),0)),"")} -> 700 | G12: =IFERROR(IF(F12>10,F12,F12*D12),"") -> 700 | I12: =IFERROR(SUM(G12+H12),"") -> 700 | J12: =IFERROR(SUM(H12+I12),"") -> 700
A13: 46154 | B13: อ.ตาคลี จ.นว | C13: JB0326106971 | D13: 148 | E13: ราคาเหมา | F13: {=IFERROR(INDEX(ราคาขนส่ง!$D$3:$D$102,MATCH(1,IF(ราคาขนส่ง!$B$3:$B$102=$B13,IF(ราคาขนส่ง!$C$3:$C$102=$E13,1)),0)),"")} -> 1300 | G13: =IFERROR(IF(F13>10,F13,F13*D13),"") -> 1300 | I13: =IFERROR(SUM(G13+H13),"") -> 1300 | J13: =IFERROR(SUM(H13+I13),"") -> 1300
A14: 46155 | B14: อ.ตาคลี จ.นว | C14: JB0326106987 | D14: 176 | E14: ราคาเหมา | F14: {=IFERROR(INDEX(ราคาขนส่ง!$D$3:$D$102,MATCH(1,IF(ราคาขนส่ง!$B$3:$B$102=$B14,IF(ราคาขนส่ง!$C$3:$C$102=$E14,1)),0)),"")} -> 1300 | G14: =IFERROR(IF(F14>10,F14,F14*D14),"") -> 1300 | I14: =IFERROR(SUM(G14+H14),"") -> 1300 | J14: =IFERROR(SUM(H14+I14),"") -> 1300
A15: 46157 | B15: อ.เมือง จ.พิจิตร | C15: JB0326107023 | D15: 125 | E15: ราคาเหมา | F15: {=IFERROR(INDEX(ราคาขนส่ง!$D$3:$D$102,MATCH(1,IF(ราคาขนส่ง!$B$3:$B$102=$B15,IF(ราคาขนส่ง!$C$3:$C$102=$E15,1)),0)),"")} -> 1650 | G15: =IFERROR(IF(F15>10,F15,F15*D15),"") -> 1650 | I15: =IFERROR(SUM(G15+H15),"") -> 1650 | J15: =IFERROR(SUM(H15+I15),"") -> 1650
E16: ราคาชิ้น | F16: {=IFERROR(INDEX(ราคาขนส่ง!$D$3:$D$102,MATCH(1,IF(ราคาขนส่ง!$B$3:$B$102=$B16,IF(ราคาขนส่ง!$C$3:$C$102=$E16,1)),0)),"")} | G16: =IFERROR(IF(F16>10,F16,F16*D16),"") | I16: =IFERROR(SUM(G16+H16),"") | J16: =IFERROR(SUM(H16+I16),"")
B17: ยอดรวม | D17: =SUM(D5:D16) -> 1695 | I17: =SUM(I5:I16) -> 13344 | J17: =SUM(J5:J16) -> 13344
A18: สรุป
B19: รายได้ทั้งหมด | C19: =J17 -> 13344 | D19: บาท
B20: หัก 1 % | C20: =SUM(C19/100) -> 133.44 | D20: บาท
B21: หักค่าน้ำมัน | C21: =+Table45678910[[#Totals],[เป็นจำนวนเงิน(บาท)]] -> 8000 | D21: บาท
B22: =+รายการหัก!C2 -> ค่าอัพเดทบิล | C22: =+รายการหัก!C8 -> 0 | D22: บาท
B23: =+รายการหัก!D2 -> หักค่าโทรศัพท์ | C23: =+รายการหัก!D8 -> 0 | D23: บาท
B24: =+รายการหัก!E2 -> หักค่าGPS | C24: =+รายการหัก!E8 -> 0 | D24: บาท | E24: =+รายการหัก!F8 -> 0
B25: =+รายการหัก!G2 -> หักค่ายืมเงิน | C25: =+รายการหัก!G8 -> 0 | D25: บาท | E25: =+รายการหัก!H8 -> 0
B26: =+รายการหัก!I2 -> หักค่าสัญญาณGPS รายปี | C26: =+รายการหัก!I8 -> 0 | D26: บาท | E26: =+รายการหัก!J8 -> 0
B27: =+รายการหัก!K2 -> หักค่าประกัน | C27: =+รายการหัก!K8 -> 0 | D27: บาท | E27: =+รายการหัก!L8 -> 0
B28: รวมรับสุทธิ | C28: =SUM(C19-C20-C21+C22-C23-C24-C25-C26-C27) -> 5210.56 | D28: บาท
B31: ได้รับเอกสารแล้ว กรุณาตรวจสอบด้วยค่ะ ขอบคุณค่ะ

Sheet ผจ-5663(2)
A1: สรุปค่าบรรทุกรถร่วมกระจายสินค้าสาขานครสวรรค์
A2: =+รายการหัก!I1 -> รอบวันที่ 1-15 พฤษภาคม 2569 | C2: =+'ผจ-5663'!E2 -> ผจ-5663 | D2: =+'ผจ-5663'!I2 -> นายภักดี วัฒนพรหม
A4: ลำดับที่ | B4: ว.ด.ป. | C4: ใบสั่งเติมน้ำมัน | D4: เป็นจำนวนเงิน(บาท)
A5: 1 | B5: 46143 | C5: 3369 | D5: 1000
A6: 2 | B6: 46144 | C6: 3370 | D6: 1000
A7: 3 | B7: 46146 | C7: 3371 | D7: 1000
A8: 4 | B8: 46149 | C8: 3372 | D8: 1000
A9: 5 | B9: 46150 | C9: 3373 | D9: 1000
A10: 6 | B10: 46150 | C10: 3374 | D10: 500
A11: 7 | B11: 46153 | C11: 3375 | D11: 500
A12: 8 | B12: 46154 | C12: 3376 | D12: 1000
A13: 9 | B13: 46157 | C13: 3377 | D13: 1000
A14: ผลรวม | D14: =SUBTOTAL(109,Table45678910[เป็นจำนวนเงิน(บาท)]) -> 8000

Sheet ผฉ-1941
A1: สรุปค่าบรรทุกรถร่วมกระจายสินค้าสาขานครสวรรค์
A2: =+รายการหัก!I1 -> รอบวันที่ 1-15 พฤษภาคม 2569 | D2: ทะเบียน | E2: ผฉ-1941 | I2: =VLOOKUP(E2,Table22[],2,0) -> นายกมล แสงจันทร์
A3: =+รายการหัก!B1 -> เงินออกรอบ 5
A4: วันที่ขึ้นของ | B4: ปลายทาง | C4: เลขที่ใบกระจาย | D4: จำนวน/ชิ้น | E4: ค่าขนส่ง | F4: ราคา | G4: เป็นเงิน | H4: พิเศษ | I4: ราคารวม | J4: คงเหลือสุทธิ | K4: หมายเหตุ
A5: 46143 | B5: อ.เมือง จ.พิจิตร | C5: JB0326106807 | D5: 165 | E5: ราคาเหมา | F5: {=IFERROR(INDEX(ราคาขนส่ง!$D$3:$D$102,MATCH(1,IF(ราคาขนส่ง!$B$3:$B$102=$B5,IF(ราคาขนส่ง!$C$3:$C$102=$E5,1)),0)),"")} -> 1650 | G5: =IFERROR(IF(F5>10,F5,F5*D5),"") -> 1650 | I5: =IFERROR(SUM(G5+H5),"") -> 1650 | J5: =IFERROR(SUM(H5+I5),"") -> 1650
A6: 46144 | B6: อ.ชนแดน จ.พช | C6: JB0326106814 | D6: 38 | E6: ราคาชิ้น | F6: {=IFERROR(INDEX(ราคาขนส่ง!$D$3:$D$102,MATCH(1,IF(ราคาขนส่ง!$B$3:$B$102=$B6,IF(ราคาขนส่ง!$C$3:$C$102=$E6,1)),0)),"")} -> 7.8 | G6: =IFERROR(IF(F6>10,F6,F6*D6),"") -> 296.4 | I6: =IFERROR(SUM(G6+H6),"") -> 296.4 | J6: =IFERROR(SUM(H6+I6),"") -> 296.4
B7: อ.เมือง จ.พช | D7: 394 | E7: ราคาชิ้น | F7: {=IFERROR(INDEX(ราคาขนส่ง!$D$3:$D$102,MATCH(1,IF(ราคาขนส่ง!$B$3:$B$102=$B7,IF(ราคาขนส่ง!$C$3:$C$102=$E7,1)),0)),"")} -> 9.3 | G7: =IFERROR(IF(F7>10,F7,F7*D7),"") -> 3664.2 | I7: =IFERROR(SUM(G7+H7),"") -> 3664.2 | J7: =IFERROR(SUM(H7+I7),"") -> 3664.2
A8: 46147 | B8: อ.เมือง จ.พิจิตร | C8: JB0326106851 | D8: 160 | E8: ราคาเหมา | F8: {=IFERROR(INDEX(ราคาขนส่ง!$D$3:$D$102,MATCH(1,IF(ราคาขนส่ง!$B$3:$B$102=$B8,IF(ราคาขนส่ง!$C$3:$C$102=$E8,1)),0)),"")} -> 1650 | G8: =IFERROR(IF(F8>10,F8,F8*D8),"") -> 1650 | I8: =IFERROR(SUM(G8+H8),"") -> 1650 | J8: =IFERROR(SUM(H8+I8),"") -> 1650
A9: 46148 | B9: อ.เมือง จ.นว | C9: JB0326106879 | D9: 250 | E9: ราคาชิ้น | F9: {=IFERROR(INDEX(ราคาขนส่ง!$D$3:$D$102,MATCH(1,IF(ราคาขนส่ง!$B$3:$B$102=$B9,IF(ราคาขนส่ง!$C$3:$C$102=$E9,1)),0)),"")} -> 3 | G9: =IFERROR(IF(F9>10,F9,F9*D9),"") -> 750 | I9: =IFERROR(SUM(G9+H9),"") -> 750 | J9: =IFERROR(SUM(H9+I9),"") -> 750
A10: 46148 | B10: อ.เมือง จ.นว | C10: JB0326106880 | D10: 116 | E10: ราคาชิ้น | F10: {=IFERROR(INDEX(ราคาขนส่ง!$D$3:$D$102,MATCH(1,IF(ราคาขนส่ง!$B$3:$B$102=$B10,IF(ราคาขนส่ง!$C$3:$C$102=$E10,1)),0)),"")} -> 3 | G10: =IFERROR(IF(F10>10,F10,F10*D10),"") -> 348 | I10: =IFERROR(SUM(G10+H10),"") -> 348 | J10: =IFERROR(SUM(H10+I10),"") -> 348
A11: 46149 | B11: อ.เมือง จ.พิจิตร | C11: JB0326106889 | D11: 171 | E11: ราคาเหมา | F11: {=IFERROR(INDEX(ราคาขนส่ง!$D$3:$D$102,MATCH(1,IF(ราคาขนส่ง!$B$3:$B$102=$B11,IF(ราคาขนส่ง!$C$3:$C$102=$E11,1)),0)),"")} -> 1650 | G11: =IFERROR(IF(F11>10,F11,F11*D11),"") -> 1650 | I11: =IFERROR(SUM(G11+H11),"") -> 1650 | J11: =IFERROR(SUM(H11+I11),"") -> 1650
A12: 46149 | B12: อ.เมือง จ.นว | C12: JB0326106906 | D12: 350 | E12: ราคาชิ้น | F12: {=IFERROR(INDEX(ราคาขนส่ง!$D$3:$D$102,MATCH(1,IF(ราคาขนส่ง!$B$3:$B$102=$B12,IF(ราคาขนส่ง!$C$3:$C$102=$E12,1)),0)),"")} -> 3 | G12: =IFERROR(IF(F12>10,F12,F12*D12),"") -> 1050 | I12: =IFERROR(SUM(G12+H12),"") -> 1050 | J12: =IFERROR(SUM(H12+I12),"") -> 1050
A13: 46150 | B13: อ.เมือง จ.นว | C13: JB0326106910 | D13: 274 | E13: ราคาชิ้น | F13: {=IFERROR(INDEX(ราคาขนส่ง!$D$3:$D$102,MATCH(1,IF(ราคาขนส่ง!$B$3:$B$102=$B13,IF(ราคาขนส่ง!$C$3:$C$102=$E13,1)),0)),"")} -> 3 | G13: =IFERROR(IF(F13>10,F13,F13*D13),"") -> 822 | I13: =IFERROR(SUM(G13+H13),"") -> 822 | J13: =IFERROR(SUM(H13+I13),"") -> 822
A14: 46151 | B14: อ.เมือง จ.ชัยนาท | C14: JB0326106922 | D14: 142 | E14: ราคาเหมา | F14: {=IFERROR(INDEX(ราคาขนส่ง!$D$3:$D$102,MATCH(1,IF(ราคาขนส่ง!$B$3:$B$102=$B14,IF(ราคาขนส่ง!$C$3:$C$102=$E14,1)),0)),"")} -> 1300 | G14: =IFERROR(IF(F14>10,F14,F14*D14),"") -> 1300 | I14: =IFERROR(SUM(G14+H14),"") -> 1300 | J14: =IFERROR(SUM(H14+I14),"") -> 1300
A15: 46153 | B15: อ.เมือง จ.พช | C15: JB0326106948 | D15: 201 | E15: ราคาเหมา | F15: {=IFERROR(INDEX(ราคาขนส่ง!$D$3:$D$102,MATCH(1,IF(ราคาขนส่ง!$B$3:$B$102=$B15,IF(ราคาขนส่ง!$C$3:$C$102=$E15,1)),0)),"")} -> 2500 | G15: =IFERROR(IF(F15>10,F15,F15*D15),"") -> 2500 | I15: =IFERROR(SUM(G15+H15),"") -> 2500 | J15: =IFERROR(SUM(H15+I15),"") -> 2500
A16: 46154 | B16: อ.เมือง จ.นว | C16: JB0326106968 | D16: 150 | E16: ราคาชิ้น | F16: {=IFERROR(INDEX(ราคาขนส่ง!$D$3:$D$102,MATCH(1,IF(ราคาขนส่ง!$B$3:$B$102=$B16,IF(ราคาขนส่ง!$C$3:$C$102=$E16,1)),0)),"")} -> 3 | G16: =IFERROR(IF(F16>10,F16,F16*D16),"") -> 450 | I16: =IFERROR(SUM(G16+H16),"") -> 450 | J16: =IFERROR(SUM(H16+I16),"") -> 450
A17: 46154 | B17: อ.ตะพานหิน จ.พิจิตร | C17: JB0326106969 | D17: 147 | E17: ราคาเหมา | F17: {=IFERROR(INDEX(ราคาขนส่ง!$D$3:$D$102,MATCH(1,IF(ราคาขนส่ง!$B$3:$B$102=$B17,IF(ราคาขนส่ง!$C$3:$C$102=$E17,1)),0)),"")} -> 1650 | G17: =IFERROR(IF(F17>10,F17,F17*D17),"") -> 1650 | I17: =IFERROR(SUM(G17+H17),"") -> 1650 | J17: =IFERROR(SUM(H17+I17),"") -> 1650
A18: 46155 | B18: อ.เมือง จ.พช | C18: JB0326106997 | D18: 499 | E18: ราคาชิ้น | F18: {=IFERROR(INDEX(ราคาขนส่ง!$D$3:$D$102,MATCH(1,IF(ราคาขนส่ง!$B$3:$B$102=$B18,IF(ราคาขนส่ง!$C$3:$C$102=$E18,1)),0)),"")} -> 9.3 | G18: =IFERROR(IF(F18>10,F18,F18*D18),"") -> 4640.7 | I18: =IFERROR(SUM(G18+H18),"") -> 4640.7 | J18: =IFERROR(SUM(H18+I18),"") -> 4640.7 | K18: มีหาร
B19: อ.หนองไผ่ จ.พช | D19: 1 | E19: ราคาชิ้น | F19: {=IFERROR(INDEX(ราคาขนส่ง!$D$3:$D$102,MATCH(1,IF(ราคาขนส่ง!$B$3:$B$102=$B19,IF(ราคาขนส่ง!$C$3:$C$102=$E19,1)),0)),"")} -> 7.8 | G19: =IFERROR(IF(F19>10,F19,F19*D19),"") -> 7.8 | I19: =IFERROR(SUM(G19+H19),"") -> 7.8 | J19: =IFERROR(SUM(H19+I19),"") -> 7.8
A20: 46157 | B20: อ.เมือง จ.พช | C20: JB0326107030 | D20: 114 | E20: ราคาเหมา | F20: {=IFERROR(INDEX(ราคาขนส่ง!$D$3:$D$102,MATCH(1,IF(ราคาขนส่ง!$B$3:$B$102=$B20,IF(ราคาขนส่ง!$C$3:$C$102=$E20,1)),0)),"")} -> 2500 | G20: =IFERROR(IF(F20>10,F20,F20*D20),"") -> 2500 | I20: =IFERROR(SUM(G20+H20),"") -> 2500 | J20: =IFERROR(SUM(H20+I20),"") -> 2500
E21: ราคาชิ้น | F21: {=IFERROR(INDEX(ราคาขนส่ง!$D$3:$D$102,MATCH(1,IF(ราคาขนส่ง!$B$3:$B$102=$B21,IF(ราคาขนส่ง!$C$3:$C$102=$E21,1)),0)),"")} | G21: =IFERROR(IF(F21>10,F21,F21*D21),"") | I21: =IFERROR(SUM(G21+H21),"") | J21: =IFERROR(SUM(H21+I21),"")
B22: ยอดรวม | D22: =SUM(D5:D21) -> 3172 | I22: =SUM(I5:I21) -> 24929.1 | J22: =SUM(J5:J21) -> 24929.1
A23: สรุป
B24: รายได้ทั้งหมด | C24: =J22 -> 24929.1 | D24: บาท
B25: หัก 1 % | C25: =SUM(C24/100) -> 249.291 | D25: บาท
B26: หักค่าน้ำมัน | C26: =+Table45678910111213[[#Totals],[เป็นจำนวนเงิน(บาท)]] -> 11500 | D26: บาท
B27: =+รายการหัก!C2 -> ค่าอัพเดทบิล | C27: =+รายการหัก!C10 -> 0 | D27: บาท
B28: =+รายการหัก!D2 -> หักค่าโทรศัพท์ | C28: =+รายการหัก!D10 -> 0 | D28: บาท
B29: =+รายการหัก!E2 -> หักค่าGPS | C29: =+รายการหัก!E10 -> 0 | D29: บาท | E29: =+รายการหัก!F10 -> 0
B30: =+รายการหัก!G2 -> หักค่ายืมเงิน | C30: =+รายการหัก!G10 -> 0 | D30: บาท | E30: =+รายการหัก!H10 -> 0
B31: =+รายการหัก!I2 -> หักค่าสัญญาณGPS รายปี | C31: =+รายการหัก!I10 -> 0 | D31: บาท | E31: =+รายการหัก!J10 -> 0
B32: =+รายการหัก!K2 -> หักค่าประกัน | C32: =+รายการหัก!K10 -> 0 | D32: บาท | E32: =+รายการหัก!L10 -> 0
B33: รวมรับสุทธิ | C33: =SUM(C24-C25-C26+C27-C28-C29-C30-C31-C32) -> 13179.809 | D33: บาท
B34: ได้รับเอกสารแล้ว กรุณาตรวจสอบด้วยค่ะ ขอบคุณค่ะ

Sheet ผฉ-1941(2)
A1: สรุปค่าบรรทุกรถร่วมกระจายสินค้าสาขานครสวรรค์
A2: =+รายการหัก!I1 -> รอบวันที่ 1-15 พฤษภาคม 2569 | C2: =+'ผฉ-1941'!E2 -> ผฉ-1941 | D2: =+'ผฉ-1941'!I2 -> นายกมล แสงจันทร์
A4: ลำดับที่ | B4: ว.ด.ป. | C4: ใบสั่งเติมน้ำมัน | D4: เป็นจำนวนเงิน(บาท)
A5: 1 | B5: 46143 | C5: 3612 | D5: 1000
A6: 2 | B6: 46143 | C6: 3613 | D6: 2000
A7: 3 | B7: 46146 | C7: 3614 | D7: 500
A8: 4 | B8: 46148 | C8: 3615 | D8: 1000
A9: 5 | B9: 46150 | C9: 3616 | D9: 1000
A10: 6 | B10: 46151 | C10: 3617 | D10: 1500
A11: 7 | B11: 46153 | C11: 3618 | D11: 500
A12: 8 | B12: 46154 | C12: 3619 | D12: 2000
A13: 10 | B13: 46156 | C13: 3620 | D13: 2000
A14: ผลรวม | D14: =SUBTOTAL(109,Table45678910111213[เป็นจำนวนเงิน(บาท)]) -> 11500

Sheet ผฉ-3572
A1: สรุปค่าบรรทุกรถร่วมกระจายสินค้าสาขานครสวรรค์
A2: =+รายการหัก!I1 -> รอบวันที่ 1-15 พฤษภาคม 2569 | D2: ทะเบียน | E2: ผฉ-3572 | I2: =VLOOKUP(E2,Table22[],2,0) -> นายสุทัศน์ เสือเลี้ยง
A3: =+รายการหัก!B1 -> เงินออกรอบ 5
A4: วันที่ขึ้นของ | B4: ปลายทาง | C4: เลขที่ใบกระจาย | D4: จำนวน/ชิ้น | E4: ค่าขนส่ง | F4: ราคา | G4: เป็นเงิน | H4: พิเศษ | I4: ราคารวม | J4: คงเหลือสุทธิ | K4: หมายเหตุ
A5: 46143 | B5: อ.หนองไผ่ จ.พช | C5: JB0326106804 | D5: 2 | E5: ราคาชิ้น | F5: {=IFERROR(INDEX(ราคาขนส่ง!$D$3:$D$102,MATCH(1,IF(ราคาขนส่ง!$B$3:$B$102=$B5,IF(ราคาขนส่ง!$C$3:$C$102=$E5,1)),0)),"")} -> 7.8 | G5: =IFERROR(IF(F5>10,F5,F5*D5),"") -> 15.6 | I5: =IFERROR(SUM(G5+H5),"") -> 15.6 | J5: =IFERROR(SUM(H5+I5),"") -> 15.6
B6: อ.เมือง จ.พช | D6: 429 | E6: ราคาชิ้น | F6: {=IFERROR(INDEX(ราคาขนส่ง!$D$3:$D$102,MATCH(1,IF(ราคาขนส่ง!$B$3:$B$102=$B6,IF(ราคาขนส่ง!$C$3:$C$102=$E6,1)),0)),"")} -> 9.3 | G6: =IFERROR(IF(F6>10,F6,F6*D6),"") -> 3989.7 | I6: =IFERROR(SUM(G6+H6),"") -> 3989.7 | J6: =IFERROR(SUM(H6+I6),"") -> 3989.7
A7: 46144 | B7: อ.เมือง จ.พิจิตร | C7: JB0326106810 | D7: 533 | E7: ราคาชิ้น | F7: {=IFERROR(INDEX(ราคาขนส่ง!$D$3:$D$102,MATCH(1,IF(ราคาขนส่ง!$B$3:$B$102=$B7,IF(ราคาขนส่ง!$C$3:$C$102=$E7,1)),0)),"")} -> 6.5 | G7: =IFERROR(IF(F7>10,F7,F7*D7),"") -> 3464.5 | I7: =IFERROR(SUM(G7+H7),"") -> 3464.5 | J7: =IFERROR(SUM(H7+I7),"") -> 3464.5
A8: 46145 | B8: อ.ตะพานหิน จ.พิจิตร | C8: JB0326106827 | D8: 158 | E8: ราคาเหมา | F8: {=IFERROR(INDEX(ราคาขนส่ง!$D$3:$D$102,MATCH(1,IF(ราคาขนส่ง!$B$3:$B$102=$B8,IF(ราคาขนส่ง!$C$3:$C$102=$E8,1)),0)),"")} -> 1650 | G8: =IFERROR(IF(F8>10,F8,F8*D8),"") -> 1650 | I8: =IFERROR(SUM(G8+H8),"") -> 1650 | J8: =IFERROR(SUM(H8+I8),"") -> 1650
A9: 46146 | B9: อ.ตะพานหิน จ.พิจิตร | C9: JB0326106828 | D9: 160 | E9: ราคาเหมา | F9: {=IFERROR(INDEX(ราคาขนส่ง!$D$3:$D$102,MATCH(1,IF(ราคาขนส่ง!$B$3:$B$102=$B9,IF(ราคาขนส่ง!$C$3:$C$102=$E9,1)),0)),"")} -> 1650 | G9: =IFERROR(IF(F9>10,F9,F9*D9),"") -> 1650 | I9: =IFERROR(SUM(G9+H9),"") -> 1650 | J9: =IFERROR(SUM(H9+I9),"") -> 1650
A10: 46146 | B10: อ.บางมูลนาก จ.พิจิตร | C10: JB0326106842 | D10: 13 | E10: ราคาชิ้น | F10: {=IFERROR(INDEX(ราคาขนส่ง!$D$3:$D$102,MATCH(1,IF(ราคาขนส่ง!$B$3:$B$102=$B10,IF(ราคาขนส่ง!$C$3:$C$102=$E10,1)),0)),"")} -> 5.6 | G10: =IFERROR(IF(F10>10,F10,F10*D10),"") -> 72.8 | I10: =IFERROR(SUM(G10+H10),"") -> 72.8 | J10: =IFERROR(SUM(H10+I10),"") -> 72.8
B11: อ.ตะพานหิน จ.พิจิตร | D11: 458 | E11: ราคาชิ้น | F11: {=IFERROR(INDEX(ราคาขนส่ง!$D$3:$D$102,MATCH(1,IF(ราคาขนส่ง!$B$3:$B$102=$B11,IF(ราคาขนส่ง!$C$3:$C$102=$E11,1)),0)),"")} -> 6.5 | G11: =IFERROR(IF(F11>10,F11,F11*D11),"") -> 2977 | I11: =IFERROR(SUM(G11+H11),"") -> 2977 | J11: =IFERROR(SUM(H11+I11),"") -> 2977
A12: 46147 | B12: อ.ตะพานหิน จ.พิจิตร | C12: JB0326106837 | D12: 445 | E12: ราคาชิ้น | F12: {=IFERROR(INDEX(ราคาขนส่ง!$D$3:$D$102,MATCH(1,IF(ราคาขนส่ง!$B$3:$B$102=$B12,IF(ราคาขนส่ง!$C$3:$C$102=$E12,1)),0)),"")} -> 6.5 | G12: =IFERROR(IF(F12>10,F12,F12*D12),"") -> 2892.5 | I12: =IFERROR(SUM(G12+H12),"") -> 2892.5 | J12: =IFERROR(SUM(H12+I12),"") -> 2892.5
A13: 46147 | B13: อ.ตะพานหิน จ.พิจิตร | C13: JB0326106888 | D13: 163 | E13: ราคาเหมา | F13: {=IFERROR(INDEX(ราคาขนส่ง!$D$3:$D$102,MATCH(1,IF(ราคาขนส่ง!$B$3:$B$102=$B13,IF(ราคาขนส่ง!$C$3:$C$102=$E13,1)),0)),"")} -> 1650 | G13: =IFERROR(IF(F13>10,F13,F13*D13),"") -> 1650 | I13: =IFERROR(SUM(G13+H13),"") -> 1650 | J13: =IFERROR(SUM(H13+I13),"") -> 1650
A14: 46148 | B14: อ.เมือง จ.พิจิตร | C14: JB0326106891 | D14: 163 | E14: ราคาเหมา | F14: {=IFERROR(INDEX(ราคาขนส่ง!$D$3:$D$102,MATCH(1,IF(ราคาขนส่ง!$B$3:$B$102=$B14,IF(ราคาขนส่ง!$C$3:$C$102=$E14,1)),0)),"")} -> 1650 | G14: =IFERROR(IF(F14>10,F14,F14*D14),"") -> 1650 | I14: =IFERROR(SUM(G14+H14),"") -> 1650 | J14: =IFERROR(SUM(H14+I14),"") -> 1650
A15: 46150 | B15: อ.เมือง จ.พช | C15: JB0326106908 | D15: 226 | E15: ราคาเหมา | F15: {=IFERROR(INDEX(ราคาขนส่ง!$D$3:$D$102,MATCH(1,IF(ราคาขนส่ง!$B$3:$B$102=$B15,IF(ราคาขนส่ง!$C$3:$C$102=$E15,1)),0)),"")} -> 2500 | G15: =IFERROR(IF(F15>10,F15,F15*D15),"") -> 2500 | I15: =IFERROR(SUM(G15+H15),"") -> 2500 | J15: =IFERROR(SUM(H15+I15),"") -> 2500
A16: 46151 | B16: อ.ตะพานหิน จ.พิจิตร | C16: JB0326106930 | D16: 147 | E16: ราคาเหมา | F16: {=IFERROR(INDEX(ราคาขนส่ง!$D$3:$D$102,MATCH(1,IF(ราคาขนส่ง!$B$3:$B$102=$B16,IF(ราคาขนส่ง!$C$3:$C$102=$E16,1)),0)),"")} -> 1650 | G16: =IFERROR(IF(F16>10,F16,F16*D16),"") -> 1650 | I16: =IFERROR(SUM(G16+H16),"") -> 1650 | J16: =IFERROR(SUM(H16+I16),"") -> 1650
A17: 46152 | B17: อ.เมือง จ.พิจิตร | C17: JB0326106949 | D17: 100 | E17: ราคาเหมา | F17: {=IFERROR(INDEX(ราคาขนส่ง!$D$3:$D$102,MATCH(1,IF(ราคาขนส่ง!$B$3:$B$102=$B17,IF(ราคาขนส่ง!$C$3:$C$102=$E17,1)),0)),"")} -> 1650 | G17: =IFERROR(IF(F17>10,F17,F17*D17),"") -> 1650 | I17: =IFERROR(SUM(G17+H17),"") -> 1650 | J17: =IFERROR(SUM(H17+I17),"") -> 1650
A18: 46153 | B18: อ.เมือง จ.พิจิตร | C18: JB0326106950 | D18: 154 | E18: ราคาเหมา | F18: {=IFERROR(INDEX(ราคาขนส่ง!$D$3:$D$102,MATCH(1,IF(ราคาขนส่ง!$B$3:$B$102=$B18,IF(ราคาขนส่ง!$C$3:$C$102=$E18,1)),0)),"")} -> 1650 | G18: =IFERROR(IF(F18>10,F18,F18*D18),"") -> 1650 | I18: =IFERROR(SUM(G18+H18),"") -> 1650 | J18: =IFERROR(SUM(H18+I18),"") -> 1650
A19: 46154 | B19: อ.เมือง จ.พช | C19: JB0326106970 | D19: 420 | E19: ราคาชิ้น | F19: {=IFERROR(INDEX(ราคาขนส่ง!$D$3:$D$102,MATCH(1,IF(ราคาขนส่ง!$B$3:$B$102=$B19,IF(ราคาขนส่ง!$C$3:$C$102=$E19,1)),0)),"")} -> 9.3 | G19: =IFERROR(IF(F19>10,F19,F19*D19),"") -> 3906 | I19: =IFERROR(SUM(G19+H19),"") -> 3906 | J19: =IFERROR(SUM(H19+I19),"") -> 3906
A20: 46155 | B20: อ.ทับคล้อ จ.พิจิตร | C20: JB0326106988 | D20: 191 | E20: ราคาเหมา | F20: {=IFERROR(INDEX(ราคาขนส่ง!$D$3:$D$102,MATCH(1,IF(ราคาขนส่ง!$B$3:$B$102=$B20,IF(ราคาขนส่ง!$C$3:$C$102=$E20,1)),0)),"")} -> 1650 | G20: =IFERROR(IF(F20>10,F20,F20*D20),"") -> 1650 | I20: =IFERROR(SUM(G20+H20),"") -> 1650 | J20: =IFERROR(SUM(H20+I20),"") -> 1650
A21: 46156 | B21: อ.เมือง จ.อุทัย | C21: JB0326107007 | D21: 159 | E21: ราคาเหมา | F21: {=IFERROR(INDEX(ราคาขนส่ง!$D$3:$D$102,MATCH(1,IF(ราคาขนส่ง!$B$3:$B$102=$B21,IF(ราคาขนส่ง!$C$3:$C$102=$E21,1)),0)),"")} -> 1300 | G21: =IFERROR(IF(F21>10,F21,F21*D21),"") -> 1300 | I21: =IFERROR(SUM(G21+H21),"") -> 1300 | J21: =IFERROR(SUM(H21+I21),"") -> 1300
A22: 46157 | B22: อ.เมือง จ.พิจิตร | C22: JB0326107022 | D22: 141 | E22: ราคาเหมา | F22: {=IFERROR(INDEX(ราคาขนส่ง!$D$3:$D$102,MATCH(1,IF(ราคาขนส่ง!$B$3:$B$102=$B22,IF(ราคาขนส่ง!$C$3:$C$102=$E22,1)),0)),"")} -> 1650 | G22: =IFERROR(IF(F22>10,F22,F22*D22),"") -> 1650 | I22: =IFERROR(SUM(G22+H22),"") -> 1650 | J22: =IFERROR(SUM(H22+I22),"") -> 1650
E23: ราคาชิ้น | F23: {=IFERROR(INDEX(ราคาขนส่ง!$D$3:$D$102,MATCH(1,IF(ราคาขนส่ง!$B$3:$B$102=$B23,IF(ราคาขนส่ง!$C$3:$C$102=$E23,1)),0)),"")} | G23: =IFERROR(IF(F23>10,F23,F23*D23),"") | I23: =IFERROR(SUM(G23+H23),"") | J23: =IFERROR(SUM(H23+I23),"")
B24: ยอดรวม | D24: =SUM(D5:D23) -> 4062 | I24: =SUM(I5:I23) -> 35968.1 | J24: =SUM(J5:J23) -> 35968.1
A25: สรุป
B26: รายได้ทั้งหมด | C26: =J24 -> 35968.1 | D26: บาท
B27: หัก 1 % | C27: =SUM(C26/100) -> 359.681 | D27: บาท
B28: หักค่าน้ำมัน | C28: =+Table4567891011121314[[#Totals],[เป็นจำนวนเงิน(บาท)]] -> 12500 | D28: บาท
B29: =+รายการหัก!C2 -> ค่าอัพเดทบิล | C29: =+รายการหัก!C11 -> 0 | D29: บาท
B30: =+รายการหัก!D2 -> หักค่าโทรศัพท์ | C30: =+รายการหัก!D11 -> 0 | D30: บาท
B31: =+รายการหัก!E2 -> หักค่าGPS | C31: =+รายการหัก!E11 -> 0 | D31: บาท | E31: =+รายการหัก!F11 -> 0
B32: =+รายการหัก!G2 -> หักค่ายืมเงิน | C32: =+รายการหัก!G11 -> 0 | D32: บาท | E32: =+รายการหัก!H11 -> 0
B33: =+รายการหัก!I2 -> หักค่าสัญญาณGPS รายปี | C33: =+รายการหัก!I11 -> 0 | D33: บาท | E33: =+รายการหัก!J11 -> 0
B34: =+รายการหัก!K2 -> หักค่าประกัน | C34: =+รายการหัก!K11 -> 0 | D34: บาท | E34: =+รายการหัก!L11 -> 0
B35: รวมรับสุทธิ | C35: =SUM(C26-C27-C28+C29-C30-C31-C32-C33-C34) -> 23108.419 | D35: บาท
B36: ได้รับเอกสารแล้ว กรุณาตรวจสอบด้วยค่ะ ขอบคุณค่ะ

Sheet ผฉ-3572(2)
A1: สรุปค่าบรรทุกรถร่วมกระจายสินค้าสาขานครสวรรค์
A2: =+รายการหัก!I1 -> รอบวันที่ 1-15 พฤษภาคม 2569 | C2: =+'ผฉ-3572'!E2 -> ผฉ-3572 | D2: =+'ผฉ-3572'!I2 -> นายสุทัศน์ เสือเลี้ยง
A4: ลำดับที่ | B4: ว.ด.ป. | C4: ใบสั่งเติมน้ำมัน | D4: เป็นจำนวนเงิน(บาท)
A5: 1 | B5: 46143 | C5: 2938 | D5: 1500
A6: 2 | B6: 46143 | C6: 2939 | D6: 1000
A7: 3 | B7: 46146 | C7: 2940 | D7: 1000
A8: 4 | B8: 46147 | C8: 2941 | D8: 1000
A9: 5 | B9: 46148 | C9: 2942 | D9: 1000
A10: 6 | B10: 46149 | C10: 2943 | D10: 1500
A11: 7 | B11: 46150 | C11: 2944 | D11: 1000
A12: 8 | B12: 46151 | C12: 2945 | D12: 1000
A13: 9 | B13: 46153 | C13: 2946 | D13: 1000
A14: 10 | B14: 46154 | C14: 2947 | D14: 1000
A15: 11 | B15: 46155 | C15: 2948 | D15: 500
A16: 12 | B16: 46156 | C16: 2949 | D16: 1000
A17: ผลรวม | D17: =SUBTOTAL(109,Table4567891011121314[เป็นจำนวนเงิน(บาท)]) -> 12500

Sheet 3ฒพ-5552
A1: สรุปค่าบรรทุกรถร่วมกระจายสินค้าสาขานครสวรรค์
A2: =+รายการหัก!I1 -> รอบวันที่ 1-15 พฤษภาคม 2569 | D2: ทะเบียน | E2: 3ฒพ-5552 | I2: =VLOOKUP(E2,Table22[],2,0) -> นายสุเมธ ทรัพย์สำราญ
A3: =+รายการหัก!B1 -> เงินออกรอบ 5
A4: วันที่ขึ้นของ | B4: ปลายทาง | C4: เลขที่ใบกระจาย | D4: จำนวน/ชิ้น | E4: ค่าขนส่ง | F4: ราคา | G4: เป็นเงิน | H4: พิเศษ | I4: ราคารวม | J4: คงเหลือสุทธิ | K4: หมายเหตุ
E8: ราคาเหมา | F8: {=IFERROR(INDEX(ราคาขนส่ง!$D$3:$D$102,MATCH(1,IF(ราคาขนส่ง!$B$3:$B$102=$B8,IF(ราคาขนส่ง!$C$3:$C$102=$E8,1)),0)),"")} | G8: =IFERROR(IF(F8>10,F8,F8*D8),"") | I8: =IFERROR(SUM(G8+H8),"") | J8: =IFERROR(SUM(H8+I8),"")
B9: ยอดรวม | D9: =SUM(D5:D8) -> 0 | I9: =SUM(I5:I8) -> 0 | J9: =SUM(J5:J8) -> 0
A10: สรุป
B11: รายได้ทั้งหมด | C11: =J9 -> 0 | D11: บาท
B12: หัก 1 % | C12: =SUM(C11/100) -> 0 | D12: บาท
B13: หักค่าน้ำมัน | C13: =+Table45678910111213141517181920212228[[#Totals],[เป็นจำนวนเงิน(บาท)]] -> 0 | D13: บาท
B14: =+รายการหัก!C2 -> ค่าอัพเดทบิล | C14: =+รายการหัก!C15 -> 0 | D14: บาท
B15: =+รายการหัก!D2 -> หักค่าโทรศัพท์ | C15: =+รายการหัก!D15 -> 0 | D15: บาท
B16: =+รายการหัก!E2 -> หักค่าGPS | C16: =+รายการหัก!E15 -> 0 | D16: บาท | E16: =+รายการหัก!F15 -> 0
B17: =+รายการหัก!G2 -> หักค่ายืมเงิน | C17: =+รายการหัก!G15 -> 0 | D17: บาท | E17: =+รายการหัก!H15 -> 0
B18: =+รายการหัก!I2 -> หักค่าสัญญาณGPS รายปี | C18: =+รายการหัก!I15 -> 0 | D18: บาท | E18: =+รายการหัก!J15 -> 0
B19: =+รายการหัก!K2 -> หักค่าประกัน | C19: =+รายการหัก!K15 -> 0 | D19: บาท | E19: =+รายการหัก!L15 -> 0
B20: รวมรับสุทธิ | C20: =SUM(C11-C12-C13+C14-C15-C16-C17-C18-C19) -> 0 | D20: บาท
B23: ได้รับเอกสารแล้ว กรุณาตรวจสอบด้วยค่ะ ขอบคุณค่ะ

Sheet 3ฒพ-5552(2)
A1: สรุปค่าบรรทุกรถร่วมกระจายสินค้าสาขานครสวรรค์
A2: =+รายการหัก!I1 -> รอบวันที่ 1-15 พฤษภาคม 2569 | C2: =+'3ฒพ-5552'!E2 -> 3ฒพ-5552 | D2: =+'3ฒพ-5552'!I2 -> นายสุเมธ ทรัพย์สำราญ
A4: ลำดับที่ | B4: ว.ด.ป. | C4: ใบสั่งเติมน้ำมัน | D4: เป็นจำนวนเงิน(บาท)
A6: ผลรวม | D6: =SUBTOTAL(109,Table45678910111213141517181920212228[เป็นจำนวนเงิน(บาท)]) -> 0

Sheet ผท-4890
A1: สรุปค่าบรรทุกรถร่วมกระจายสินค้าสาขานครสวรรค์
A2: =+รายการหัก!I1 -> รอบวันที่ 1-15 พฤษภาคม 2569 | D2: ทะเบียน | E2: ผท-4890 | I2: =VLOOKUP(E2,Table22[],2,0) -> นายกัมปนาจ คุ้มอักษร
A3: =+รายการหัก!B1 -> เงินออกรอบ 5
A4: วันที่ขึ้นของ | B4: ปลายทาง | C4: เลขที่ใบกระจาย | D4: จำนวน/ชิ้น | E4: ค่าขนส่ง | F4: ราคา | G4: เป็นเงิน | H4: พิเศษ | I4: ราคารวม | J4: คงเหลือสุทธิ | K4: หมายเหตุ
A5: 46143 | B5: อ.เมือง จ.พิจิตร | C5: JB0326106805 | D5: 172 | E5: ราคาเหมา | F5: {=IFERROR(INDEX(ราคาขนส่ง!$D$3:$D$102,MATCH(1,IF(ราคาขนส่ง!$B$3:$B$102=$B5,IF(ราคาขนส่ง!$C$3:$C$102=$E5,1)),0)),"")} -> 1650 | G5: =IFERROR(IF(F5>10,F5,F5*D5),"") -> 1650 | I5: =IFERROR(SUM(G5+H5),"") -> 1650 | J5: =IFERROR(SUM(H5+I5),"") -> 1650
A6: 46144 | B6: อ.เมือง จ.พช | C6: JB0326106815 | D6: 433 | E6: ราคาชิ้น | F6: {=IFERROR(INDEX(ราคาขนส่ง!$D$3:$D$102,MATCH(1,IF(ราคาขนส่ง!$B$3:$B$102=$B6,IF(ราคาขนส่ง!$C$3:$C$102=$E6,1)),0)),"")} -> 9.3 | G6: =IFERROR(IF(F6>10,F6,F6*D6),"") -> 4026.9 | I6: =IFERROR(SUM(G6+H6),"") -> 4026.9 | J6: =IFERROR(SUM(H6+I6),"") -> 4026.9
A7: 46147 | B7: อ.ตาคลี จ.นว | C7: JB0326106862 | D7: 146 | E7: ราคาเหมา | F7: {=IFERROR(INDEX(ราคาขนส่ง!$D$3:$D$102,MATCH(1,IF(ราคาขนส่ง!$B$3:$B$102=$B7,IF(ราคาขนส่ง!$C$3:$C$102=$E7,1)),0)),"")} -> 1300 | G7: =IFERROR(IF(F7>10,F7,F7*D7),"") -> 1300 | I7: =IFERROR(SUM(G7+H7),"") -> 1300 | J7: =IFERROR(SUM(H7+I7),"") -> 1300
A8: 46148 | B8: อ.ตาคลี จ.นว | C8: JB0326106864 | D8: 165 | E8: ราคาเหมา | F8: {=IFERROR(INDEX(ราคาขนส่ง!$D$3:$D$102,MATCH(1,IF(ราคาขนส่ง!$B$3:$B$102=$B8,IF(ราคาขนส่ง!$C$3:$C$102=$E8,1)),0)),"")} -> 1300 | G8: =IFERROR(IF(F8>10,F8,F8*D8),"") -> 1300 | I8: =IFERROR(SUM(G8+H8),"") -> 1300 | J8: =IFERROR(SUM(H8+I8),"") -> 1300
A9: 46148 | B9: อ.เมือง จ.พิจิตร | C9: JB0326106872 | D9: 122 | E9: ราคาเหมา | F9: {=IFERROR(INDEX(ราคาขนส่ง!$D$3:$D$102,MATCH(1,IF(ราคาขนส่ง!$B$3:$B$102=$B9,IF(ราคาขนส่ง!$C$3:$C$102=$E9,1)),0)),"")} -> 1650 | G9: =IFERROR(IF(F9>10,F9,F9*D9),"") -> 1650 | I9: =IFERROR(SUM(G9+H9),"") -> 1650 | J9: =IFERROR(SUM(H9+I9),"") -> 1650
A10: 46151 | B10: อ.เมือง จ.พิจิตร | C10: JB0326106923 | D10: 142 | E10: ราคาเหมา | F10: {=IFERROR(INDEX(ราคาขนส่ง!$D$3:$D$102,MATCH(1,IF(ราคาขนส่ง!$B$3:$B$102=$B10,IF(ราคาขนส่ง!$C$3:$C$102=$E10,1)),0)),"")} -> 1650 | G10: =IFERROR(IF(F10>10,F10,F10*D10),"") -> 1650 | I10: =IFERROR(SUM(G10+H10),"") -> 1650 | J10: =IFERROR(SUM(H10+I10),"") -> 1650
A11: 46152 | B11: อ.เมือง จ.พิจิตร | C11: JB0326106954 | D11: 151 | E11: ราคาเหมา | F11: {=IFERROR(INDEX(ราคาขนส่ง!$D$3:$D$102,MATCH(1,IF(ราคาขนส่ง!$B$3:$B$102=$B11,IF(ราคาขนส่ง!$C$3:$C$102=$E11,1)),0)),"")} -> 1650 | G11: =IFERROR(IF(F11>10,F11,F11*D11),"") -> 1650 | I11: =IFERROR(SUM(G11+H11),"") -> 1650 | J11: =IFERROR(SUM(H11+I11),"") -> 1650
A12: 46153 | B12: อ.เมือง จ.พิจิตร | C12: JB0326106951 | D12: 149 | E12: ราคาเหมา | F12: {=IFERROR(INDEX(ราคาขนส่ง!$D$3:$D$102,MATCH(1,IF(ราคาขนส่ง!$B$3:$B$102=$B12,IF(ราคาขนส่ง!$C$3:$C$102=$E12,1)),0)),"")} -> 1650 | G12: =IFERROR(IF(F12>10,F12,F12*D12),"") -> 1650 | I12: =IFERROR(SUM(G12+H12),"") -> 1650 | J12: =IFERROR(SUM(H12+I12),"") -> 1650
A13: 46154 | B13: อ.เมือง จ.นว | C13: JB0326106952 | D13: 225 | E13: ราคาชิ้น | F13: {=IFERROR(INDEX(ราคาขนส่ง!$D$3:$D$102,MATCH(1,IF(ราคาขนส่ง!$B$3:$B$102=$B13,IF(ราคาขนส่ง!$C$3:$C$102=$E13,1)),0)),"")} -> 3 | G13: =IFERROR(IF(F13>10,F13,F13*D13),"") -> 675 | I13: =IFERROR(SUM(G13+H13),"") -> 675 | J13: =IFERROR(SUM(H13+I13),"") -> 675
A14: 46155 | B14: อ.เมือง จ.ชัยนาท | C14: JB0326106973 | D14: 131 | E14: ราคาเหมา | F14: {=IFERROR(INDEX(ราคาขนส่ง!$D$3:$D$102,MATCH(1,IF(ราคาขนส่ง!$B$3:$B$102=$B14,IF(ราคาขนส่ง!$C$3:$C$102=$E14,1)),0)),"")} -> 1300 | G14: =IFERROR(IF(F14>10,F14,F14*D14),"") -> 1300 | I14: =IFERROR(SUM(G14+H14),"") -> 1300 | J14: =IFERROR(SUM(H14+I14),"") -> 1300
A15: 46156 | B15: อ.เมือง จ.ชัยนาท | C15: JB0326107009 | D15: 198 | E15: ราคาเหมา | F15: {=IFERROR(INDEX(ราคาขนส่ง!$D$3:$D$102,MATCH(1,IF(ราคาขนส่ง!$B$3:$B$102=$B15,IF(ราคาขนส่ง!$C$3:$C$102=$E15,1)),0)),"")} -> 1300 | G15: =IFERROR(IF(F15>10,F15,F15*D15),"") -> 1300 | I15: =IFERROR(SUM(G15+H15),"") -> 1300 | J15: =IFERROR(SUM(H15+I15),"") -> 1300
A16: 46157 | B16: อ.หันคา จ.ชัยนาท | C16: JB0326107010 | D16: 111 | E16: ราคาเหมา | F16: {=IFERROR(INDEX(ราคาขนส่ง!$D$3:$D$102,MATCH(1,IF(ราคาขนส่ง!$B$3:$B$102=$B16,IF(ราคาขนส่ง!$C$3:$C$102=$E16,1)),0)),"")} -> 1700 | G16: =IFERROR(IF(F16>10,F16,F16*D16),"") -> 1700 | I16: =IFERROR(SUM(G16+H16),"") -> 1700 | J16: =IFERROR(SUM(H16+I16),"") -> 1700
A17: 46157 | B17: อ.เมือง จ.พช | C17: JB0326107034 | D17: 145 | E17: ราคาเหมา | F17: {=IFERROR(INDEX(ราคาขนส่ง!$D$3:$D$102,MATCH(1,IF(ราคาขนส่ง!$B$3:$B$102=$B17,IF(ราคาขนส่ง!$C$3:$C$102=$E17,1)),0)),"")} -> 2500 | G17: =IFERROR(IF(F17>10,F17,F17*D17),"") -> 2500 | I17: =IFERROR(SUM(G17+H17),"") -> 2500 | J17: =IFERROR(SUM(H17+I17),"") -> 2500
F18: {=IFERROR(INDEX(ราคาขนส่ง!$D$3:$D$102,MATCH(1,IF(ราคาขนส่ง!$B$3:$B$102=#REF!,IF(ราคาขนส่ง!$C$3:$C$102=$E18,1)),0)),"")} | G18: =IFERROR(IF(F18>10,F18,F18*D18),"") | I18: =IFERROR(SUM(G18+H18),"") | J18: =IFERROR(SUM(H18+I18),"")
B19: ยอดรวม | D19: =SUM(D5:D18) -> 2290 | I19: =SUM(I5:I18) -> 22351.9 | J19: =SUM(J5:J18) -> 22351.9
A20: สรุป
B21: รายได้ทั้งหมด | C21: =J19 -> 22351.9 | D21: บาท
B22: หัก 1 % | C22: =SUM(C21/100) -> 223.519 | D22: บาท
B23: หักค่าน้ำมัน | C23: =+Table45678910111213141517181920212228323337[[#Totals],[เป็นจำนวนเงิน(บาท)]] -> 10900 | D23: บาท
B24: =+รายการหัก!C2 -> ค่าอัพเดทบิล | C24: =+รายการหัก!C16 -> 0 | D24: บาท
B25: =+รายการหัก!D2 -> หักค่าโทรศัพท์ | C25: =+รายการหัก!D16 -> 0 | D25: บาท
B26: =+รายการหัก!E2 -> หักค่าGPS | C26: =+รายการหัก!E16 -> 0 | D26: บาท | E26: =+รายการหัก!F16 -> 0
B27: =+รายการหัก!G2 -> หักค่ายืมเงิน | C27: =+รายการหัก!G16 -> 0 | D27: บาท | E27: =+รายการหัก!H16 -> 0
B28: =+รายการหัก!I2 -> หักค่าสัญญาณGPS รายปี | C28: 0 | D28: บาท | E28: =+รายการหัก!J16 -> 0
B29: =+รายการหัก!K2 -> หักค่าประกัน | C29: =+รายการหัก!K16 -> 1800 | D29: บาท | E29: =+รายการหัก!L16 -> 2
B30: รวมรับสุทธิ | C30: =SUM(C21-C22-C23+C24-C25-C26-C27-C28-C29) -> 9428.381 | D30: บาท
B31: ได้รับเอกสารแล้ว กรุณาตรวจสอบด้วยค่ะ ขอบคุณค่ะ

Sheet ผท-4890(2)
A1: สรุปค่าบรรทุกรถร่วมกระจายสินค้าสาขานครสวรรค์
A2: =+รายการหัก!I1 -> รอบวันที่ 1-15 พฤษภาคม 2569 | C2: =+'ผท-4890'!E2 -> ผท-4890 | D2: =+'ผท-4890'!I2 -> นายกัมปนาจ คุ้มอักษร
A4: ลำดับที่ | B4: ว.ด.ป. | C4: ใบสั่งเติมน้ำมัน | D4: เป็นจำนวนเงิน(บาท)
A5: 1 | B5: 46143 | C5: 3515 | D5: 1000
A6: 2 | B6: 46143 | C6: 3516 | D6: 2000
A7: 3 | B7: 46146 | C7: 3517 | D7: 1000
A8: 4 | B8: 46147 | C8: 3518 | D8: 1000
A9: 5 | B9: 46150 | C9: 3519 | D9: 1000
A10: 6 | B10: 46151 | C10: 3520 | D10: 1000
A11: 7 | B11: 46155 | C11: 3521 | D11: 1000
A12: 8 | B12: 46155 | C12: 3522 | D12: 1000
A13: 9 | B13: 46156 | C13: 3523 | D13: 1900
A14: ผลรวม | D14: =SUBTOTAL(109,Table45678910111213141517181920212228323337[เป็นจำนวนเงิน(บาท)]) -> 10900

Sheet บล-5334
A1: สรุปค่าบรรทุกรถร่วมกระจายสินค้าสาขานครสวรรค์
A2: =+รายการหัก!I1 -> รอบวันที่ 1-15 พฤษภาคม 2569 | D2: ทะเบียน | E2: บล-5334 | I2: =VLOOKUP(E2,Table22[],2,0) -> นางสาวพัชรี อุ่มชัย
A3: =+รายการหัก!B1 -> เงินออกรอบ 5
A4: วันที่ขึ้นของ | B4: ปลายทาง | C4: เลขที่ใบกระจาย | D4: จำนวน/ชิ้น | E4: ค่าขนส่ง | F4: ราคา | G4: เป็นเงิน | H4: พิเศษ | I4: ราคารวม | J4: คงเหลือสุทธิ | K4: หมายเหตุ
E5: ราคาเหมา | F5: {=IFERROR(INDEX(ราคาขนส่ง!$D$3:$D$102,MATCH(1,IF(ราคาขนส่ง!$B$3:$B$102=$B5,IF(ราคาขนส่ง!$C$3:$C$102=$E5,1)),0)),"")} | G5: =IFERROR(IF(F5>10,F5,F5*D5),"") | I5: =IFERROR(SUM(G5+H5),"") | J5: =IFERROR(SUM(H5+I5),"")
E6: ราคาเหมา | F6: {=IFERROR(INDEX(ราคาขนส่ง!$D$3:$D$102,MATCH(1,IF(ราคาขนส่ง!$B$3:$B$102=$B6,IF(ราคาขนส่ง!$C$3:$C$102=$E6,1)),0)),"")} | G6: =IFERROR(IF(F6>10,F6,F6*D6),"") | I6: =IFERROR(SUM(G6+H6),"") | J6: =IFERROR(SUM(H6+I6),"")
E7: ราคาเหมา | F7: {=IFERROR(INDEX(ราคาขนส่ง!$D$3:$D$102,MATCH(1,IF(ราคาขนส่ง!$B$3:$B$102=$B7,IF(ราคาขนส่ง!$C$3:$C$102=$E7,1)),0)),"")} | G7: =IFERROR(IF(F7>10,F7,F7*D7),"") | I7: =IFERROR(SUM(G7+H7),"") | J7: =IFERROR(SUM(H7+I7),"")
E8: ราคาเหมา | F8: {=IFERROR(INDEX(ราคาขนส่ง!$D$3:$D$102,MATCH(1,IF(ราคาขนส่ง!$B$3:$B$102=$B8,IF(ราคาขนส่ง!$C$3:$C$102=$E8,1)),0)),"")} | G8: =IFERROR(IF(F8>10,F8,F8*D8),"") | I8: =IFERROR(SUM(G8+H8),"") | J8: =IFERROR(SUM(H8+I8),"")
E9: ราคาเหมา | F9: {=IFERROR(INDEX(ราคาขนส่ง!$D$3:$D$102,MATCH(1,IF(ราคาขนส่ง!$B$3:$B$102=$B9,IF(ราคาขนส่ง!$C$3:$C$102=$E9,1)),0)),"")} | G9: =IFERROR(IF(F9>10,F9,F9*D9),"") | I9: =IFERROR(SUM(G9+H9),"") | J9: =IFERROR(SUM(H9+I9),"")
E10: ราคาชิ้น | F10: {=IFERROR(INDEX(ราคาขนส่ง!$D$3:$D$102,MATCH(1,IF(ราคาขนส่ง!$B$3:$B$102=$B10,IF(ราคาขนส่ง!$C$3:$C$102=$E10,1)),0)),"")} | G10: =IFERROR(IF(F10>10,F10,F10*D10),"") | I10: =IFERROR(SUM(G10+H10),"") | J10: =IFERROR(SUM(H10+I10),"")
F11: {=IFERROR(INDEX(ราคาขนส่ง!$D$3:$D$102,MATCH(1,IF(ราคาขนส่ง!$B$3:$B$102=$B11,IF(ราคาขนส่ง!$C$3:$C$102=$E11,1)),0)),"")} | G11: =IFERROR(IF(F11>10,F11,F11*D11),"") | I11: =IFERROR(SUM(G11+H11),"") | J11: =IFERROR(SUM(H11+I11),"")
B12: ยอดรวม | D12: =SUM(D5:D11) -> 0 | I12: =SUM(I5:I11) -> 0 | J12: =SUM(J5:J11) -> 0
A13: สรุป
B14: รายได้ทั้งหมด | C14: =J12 -> 0 | D14: บาท
B15: หัก 1 % | C15: =SUM(C14/100) -> 0 | D15: บาท
B16: หักค่าน้ำมัน | C16: =+Table456789101112131415171819202122[[#Totals],[เป็นจำนวนเงิน(บาท)]] -> 0 | D16: บาท
B17: =+รายการหัก!C2 -> ค่าอัพเดทบิล | C17: =+รายการหัก!C17 -> 0 | D17: บาท
B18: =+รายการหัก!D2 -> หักค่าโทรศัพท์ | C18: =+รายการหัก!D17 -> 0 | D18: บาท
B19: =+รายการหัก!E2 -> หักค่าGPS | C19: =+รายการหัก!E17 -> 0 | D19: บาท | E19: =+รายการหัก!F17 -> 0
B20: =+รายการหัก!G2 -> หักค่ายืมเงิน | C20: =+รายการหัก!G17 -> 0 | D20: บาท | E20: =+รายการหัก!H17 -> 0
B21: =+รายการหัก!I2 -> หักค่าสัญญาณGPS รายปี | C21: =+รายการหัก!I17 -> 0 | D21: บาท | E21: =+รายการหัก!J17 -> 0
B22: =+รายการหัก!K2 -> หักค่าประกัน | C22: =+รายการหัก!K17 -> 0 | D22: บาท | E22: =+รายการหัก!L17 -> 0
B23: รวมรับสุทธิ | C23: =SUM(C14-C15-C16+C17-C18-C19-C20-C21-C22) -> 0 | D23: บาท

Sheet บล-5334(2)
A1: สรุปค่าบรรทุกรถร่วมกระจายสินค้าสาขานครสวรรค์
A2: =+รายการหัก!I1 -> รอบวันที่ 1-15 พฤษภาคม 2569 | C2: =+'บล-5334'!E2 -> บล-5334 | D2: =+'บล-5334'!I2 -> นางสาวพัชรี อุ่มชัย
A4: ลำดับที่ | B4: ว.ด.ป. | C4: ใบสั่งเติมน้ำมัน | D4: เป็นจำนวนเงิน(บาท)
A10: ผลรวม | D10: =SUBTOTAL(109,Table456789101112131415171819202122[เป็นจำนวนเงิน(บาท)]) -> 0

Sheet ผฉ-302ตู้
A1: สรุปค่าบรรทุกรถร่วมกระจายสินค้าสาขานครสวรรค์
A2: =+รายการหัก!I1 -> รอบวันที่ 1-15 พฤษภาคม 2569 | D2: ทะเบียน | E2: ผฉ-302 ตู้ | I2: =VLOOKUP(E2,Table22[],2,0) -> นายสันติพงษ์ ทองเที่ยง
A3: =+รายการหัก!B1 -> เงินออกรอบ 5
A4: วันที่ขึ้นของ | B4: ปลายทาง | C4: เลขที่ใบกระจาย | D4: จำนวน/ชิ้น | E4: ค่าขนส่ง | F4: ราคา | G4: เป็นเงิน | H4: พิเศษ | I4: ราคารวม | J4: คงเหลือสุทธิ | K4: หมายเหตุ
A5: 46143 | B5: อ.เมือง จ.พิจิตร | C5: JB0326106812 | D5: 107 | E5: ราคาเหมา | F5: {=IFERROR(INDEX(ราคาขนส่ง!$D$3:$D$102,MATCH(1,IF(ราคาขนส่ง!$B$3:$B$102=$B5,IF(ราคาขนส่ง!$C$3:$C$102=$E5,1)),0)),"")} -> 1650 | G5: =IFERROR(IF(F5>10,F5,F5*D5),"") -> 1650 | I5: =IFERROR(SUM(G5+H5),"") -> 1650 | J5: =IFERROR(SUM(H5+I5),"") -> 1650
A6: 46144 | B6: อ.บึงสามพัน จ.พช | C6: JB0326106817 | D6: 340 | E6: ราคาชิ้น | F6: {=IFERROR(INDEX(ราคาขนส่ง!$D$3:$D$102,MATCH(1,IF(ราคาขนส่ง!$B$3:$B$102=$B6,IF(ราคาขนส่ง!$C$3:$C$102=$E6,1)),0)),"")} -> 7.8 | G6: =IFERROR(IF(F6>10,F6,F6*D6),"") -> 2652 | I6: =IFERROR(SUM(G6+H6),"") -> 2652 | J6: =IFERROR(SUM(H6+I6),"") -> 2652
A7: 46145 | B7: อ.ตะพานหิน จ.พิจิตร | C7: JB0326106847 | D7: 153 | E7: ราคาเหมา | F7: {=IFERROR(INDEX(ราคาขนส่ง!$D$3:$D$102,MATCH(1,IF(ราคาขนส่ง!$B$3:$B$102=$B7,IF(ราคาขนส่ง!$C$3:$C$102=$E7,1)),0)),"")} -> 1650 | G7: =IFERROR(IF(F7>10,F7,F7*D7),"") -> 1650 | I7: =IFERROR(SUM(G7+H7),"") -> 1650 | J7: =IFERROR(SUM(H7+I7),"") -> 1650
A8: 46146 | B8: อ.ตะพานหิน จ.พิจิตร | C8: JB0326106848 | D8: 195 | E8: ราคาเหมา | F8: {=IFERROR(INDEX(ราคาขนส่ง!$D$3:$D$102,MATCH(1,IF(ราคาขนส่ง!$B$3:$B$102=$B8,IF(ราคาขนส่ง!$C$3:$C$102=$E8,1)),0)),"")} -> 1650 | G8: =IFERROR(IF(F8>10,F8,F8*D8),"") -> 1650 | I8: =IFERROR(SUM(G8+H8),"") -> 1650 | J8: =IFERROR(SUM(H8+I8),"") -> 1650
A9: 46147 | B9: อ.เมือง จ.นว | C9: JB0326106859 | D9: 239 | E9: ราคาชิ้น | F9: {=IFERROR(INDEX(ราคาขนส่ง!$D$3:$D$102,MATCH(1,IF(ราคาขนส่ง!$B$3:$B$102=$B9,IF(ราคาขนส่ง!$C$3:$C$102=$E9,1)),0)),"")} -> 3 | G9: =IFERROR(IF(F9>10,F9,F9*D9),"") -> 717 | I9: =IFERROR(SUM(G9+H9),"") -> 717 | J9: =IFERROR(SUM(H9+I9),"") -> 717
A10: 46147 | B10: อ.เมือง จ.นว | C10: JB0326106860 | D10: 238 | E10: ราคาชิ้น | F10: {=IFERROR(INDEX(ราคาขนส่ง!$D$3:$D$102,MATCH(1,IF(ราคาขนส่ง!$B$3:$B$102=$B10,IF(ราคาขนส่ง!$C$3:$C$102=$E10,1)),0)),"")} -> 3 | G10: =IFERROR(IF(F10>10,F10,F10*D10),"") -> 714 | I10: =IFERROR(SUM(G10+H10),"") -> 714 | J10: =IFERROR(SUM(H10+I10),"") -> 714
A11: 46148 | B11: อ.หนองฉาง จ.อุทัย | C11: JB0326106885 | D11: 339 | E11: ราคาชิ้น | F11: {=IFERROR(INDEX(ราคาขนส่ง!$D$3:$D$102,MATCH(1,IF(ราคาขนส่ง!$B$3:$B$102=$B11,IF(ราคาขนส่ง!$C$3:$C$102=$E11,1)),0)),"")} -> 5.6 | G11: =IFERROR(IF(F11>10,F11,F11*D11),"") -> 1898.4 | I11: =IFERROR(SUM(G11+H11),"") -> 1898.4 | J11: =IFERROR(SUM(H11+I11),"") -> 1898.4
A12: 46149 | B12: อ.ตะพานหิน จ.พิจิตร | C12: JB0326106895 | D12: 160 | E12: ราคาเหมา | F12: {=IFERROR(INDEX(ราคาขนส่ง!$D$3:$D$102,MATCH(1,IF(ราคาขนส่ง!$B$3:$B$102=$B12,IF(ราคาขนส่ง!$C$3:$C$102=$E12,1)),0)),"")} -> 1650 | G12: =IFERROR(IF(F12>10,F12,F12*D12),"") -> 1650 | I12: =IFERROR(SUM(G12+H12),"") -> 1650 | J12: =IFERROR(SUM(H12+I12),"") -> 1650
A13: 46150 | B13: อ.เมือง จ.พิจิตร | C13: JB0326106913 | D13: 152 | E13: ราคาเหมา | F13: {=IFERROR(INDEX(ราคาขนส่ง!$D$3:$D$102,MATCH(1,IF(ราคาขนส่ง!$B$3:$B$102=$B13,IF(ราคาขนส่ง!$C$3:$C$102=$E13,1)),0)),"")} -> 1650 | G13: =IFERROR(IF(F13>10,F13,F13*D13),"") -> 1650 | I13: =IFERROR(SUM(G13+H13),"") -> 1650 | J13: =IFERROR(SUM(H13+I13),"") -> 1650
A14: 46151 | B14: อ.เมือง จ.พิจิตร | C14: JB0326106932 | D14: 110 | E14: ราคาเหมา | F14: {=IFERROR(INDEX(ราคาขนส่ง!$D$3:$D$102,MATCH(1,IF(ราคาขนส่ง!$B$3:$B$102=$B14,IF(ราคาขนส่ง!$C$3:$C$102=$E14,1)),0)),"")} -> 1650 | G14: =IFERROR(IF(F14>10,F14,F14*D14),"") -> 1650 | I14: =IFERROR(SUM(G14+H14),"") -> 1650 | J14: =IFERROR(SUM(H14+I14),"") -> 1650
A15: 46154 | B15: อ.เมือง จ.พิจิตร | C15: JB0326106979 | D15: 150 | E15: ราคาเหมา | F15: {=IFERROR(INDEX(ราคาขนส่ง!$D$3:$D$102,MATCH(1,IF(ราคาขนส่ง!$B$3:$B$102=$B15,IF(ราคาขนส่ง!$C$3:$C$102=$E15,1)),0)),"")} -> 1650 | G15: =IFERROR(IF(F15>10,F15,F15*D15),"") -> 1650 | I15: =IFERROR(SUM(G15+H15),"") -> 1650 | J15: =IFERROR(SUM(H15+I15),"") -> 1650
A16: 46155 | B16: อ.เมือง จ.พิจิตร | C16: JB0326106998 | D16: 162 | E16: ราคาเหมา | F16: {=IFERROR(INDEX(ราคาขนส่ง!$D$3:$D$102,MATCH(1,IF(ราคาขนส่ง!$B$3:$B$102=$B16,IF(ราคาขนส่ง!$C$3:$C$102=$E16,1)),0)),"")} -> 1650 | G16: =IFERROR(IF(F16>10,F16,F16*D16),"") -> 1650 | I16: =IFERROR(SUM(G16+H16),"") -> 1650 | J16: =IFERROR(SUM(H16+I16),"") -> 1650
... A19: 46156 | B19: อ.ตะพานหิน จ.พิจิตร | C19: JB0326106999 | D19: 149 | E19: ราคาเหมา | F19: {=IFERROR(INDEX(ราคาขนส่ง!$D$3:$D$102,MATCH(1,IF(ราคาขนส่ง!$B$3:$B$102=$B19,IF(ราคาขนส่ง!$C$3:$C$102=$E19,1)),0)),"")} -> 1650 | G19: =IFERROR(IF(F19>10,F19,F19*D19),"") -> 1650 | I19: =IFERROR(SUM(G19+H19),"") -> 1650 | J19: =IFERROR(SUM(H19+I19),"") -> 1650
A20: 46157 | B20: อ.เมือง จ.นว | C20: JB0326107042 | D20: 149 | E20: ราคาชิ้น | F20: {=IFERROR(INDEX(ราคาขนส่ง!$D$3:$D$102,MATCH(1,IF(ราคาขนส่ง!$B$3:$B$102=$B20,IF(ราคาขนส่ง!$C$3:$C$102=$E20,1)),0)),"")} -> 3 | G20: =IFERROR(IF(F20>10,F20,F20*D20),"") -> 447 | I20: =IFERROR(SUM(G20+H20),"") -> 447 | J20: =IFERROR(SUM(H20+I20),"") -> 447 | N20: จ่ายเกิน 253
A21: 46157 | B21: อ.เมือง จ.ชัยนาท | C21: JB0326107038 | D21: 134 | E21: ราคาเหมา | F21: {=IFERROR(INDEX(ราคาขนส่ง!$D$3:$D$102,MATCH(1,IF(ราคาขนส่ง!$B$3:$B$102=$B21,IF(ราคาขนส่ง!$C$3:$C$102=$E21,1)),0)),"")} -> 1300 | G21: =IFERROR(IF(F21>10,F21,F21*D21),"") -> 1300 | I21: =IFERROR(SUM(G21+H21),"") -> 1300 | J21: =IFERROR(SUM(H21+I21),"") -> 1300
E22: ราคาชิ้น | F22: {=IFERROR(INDEX(ราคาขนส่ง!$D$3:$D$102,MATCH(1,IF(ราคาขนส่ง!$B$3:$B$102=$B22,IF(ราคาขนส่ง!$C$3:$C$102=$E22,1)),0)),"")} | G22: =IFERROR(IF(F22>10,F22,F22*D22),"") | I22: =IFERROR(SUM(G22+H22),"") | J22: =IFERROR(SUM(H22+I22),"")
B23: ยอดรวม | D23: =SUM(D5:D22) -> 3179 | I23: =SUM(I5:I22) -> 24972.4 | J23: =SUM(J5:J22) -> 24972.4
A24: สรุป
B25: รายได้ทั้งหมด | C25: =J23 -> 24972.4 | D25: บาท
B26: หัก 1 % | C26: =SUM(C25/100) -> 249.724 | D26: บาท
B27: หักค่าน้ำมัน | C27: =+Table4567891011[[#Totals],[เป็นจำนวนเงิน(บาท)]] -> 12000 | D27: บาท
B28: =+รายการหัก!C2 -> ค่าอัพเดทบิล | C28: =+รายการหัก!C9 -> 0 | D28: บาท
B29: =+รายการหัก!D2 -> หักค่าโทรศัพท์ | C29: =+รายการหัก!D9 -> 0 | D29: บาท
B30: =+รายการหัก!E2 -> หักค่าGPS | C30: =+รายการหัก!E9 -> 0 | D30: บาท | E30: =+รายการหัก!F9 -> 0
B31: =+รายการหัก!G2 -> หักค่ายืมเงิน | C31: =+รายการหัก!G9 -> 0 | D31: บาท | E31: =+รายการหัก!H9 -> 0
B32: =+รายการหัก!I2 -> หักค่าสัญญาณGPS รายปี | C32: =+รายการหัก!I9 -> 0 | D32: บาท | E32: =+รายการหัก!J7 -> 0
B33: =+รายการหัก!K2 -> หักค่าประกัน | C33: =+รายการหัก!K9 -> 0 | D33: บาท | E33: =+รายการหัก!L9 -> 0
B34: รวมรับสุทธิ | C34: =SUM(C25-C26-C27+C28-C29-C30-C31-C32-C33) -> 12722.676 | D34: บาท
B35: ได้รับเอกสารแล้ว กรุณาตรวจสอบด้วยค่ะ ขอบคุณค่ะ

Sheet ผฉ-302ตู้(2)
A1: สรุปค่าบรรทุกรถร่วมกระจายสินค้าสาขานครสวรรค์
A2: =+รายการหัก!I1 -> รอบวันที่ 1-15 พฤษภาคม 2569 | C2: =+'ผฉ-302ตู้'!E2 -> ผฉ-302 ตู้ | D2: =+'ผฉ-302ตู้'!I2 -> นายสันติพงษ์ ทองเที่ยง
A4: ลำดับที่ | B4: ว.ด.ป. | C4: ใบสั่งเติมน้ำมัน | D4: เป็นจำนวนเงิน(บาท)
A5: 1 | B5: 46143 | C5: 2879 | D5: 2000
A6: 2 | B6: 46147 | C6: 2880 | D6: 2000
A7: 3 | B7: 46148 | C7: 2881 | D7: 1000
A8: 4 | B8: 46150 | C8: 2882 | D8: 2000
A9: 5 | B9: 46152 | C9: 2883 | D9: 1500
A10: 6 | B10: 46153 | C10: 2884 | D10: 2000
A11: 7 | B11: 46155 | C11: 2885 | D11: 1000
A12: 8 | B12: 46156 | C12: 2886 | D12: 500
A13: ผลรวม | D13: =SUBTOTAL(109,Table4567891011[เป็นจำนวนเงิน(บาท)]) -> 12000

Sheet ผฉ-3101ตู้
A1: สรุปค่าบรรทุกรถร่วมกระจายสินค้าสาขานครสวรรค์
A2: =+รายการหัก!I1 -> รอบวันที่ 1-15 พฤษภาคม 2569 | D2: ทะเบียน | E2: ผฉ-3101 ตู้ | I2: =VLOOKUP(E2,Table22[],2,0) -> นายอนุสรณ์ พิมชะนะ
A3: =+รายการหัก!B1 -> เงินออกรอบ 5
A4: วันที่ขึ้นของ | B4: ปลายทาง | C4: เลขที่ใบกระจาย | D4: จำนวน/ชิ้น | E4: ค่าขนส่ง | F4: ราคา | G4: เป็นเงิน | H4: พิเศษ | I4: ราคารวม | J4: คงเหลือสุทธิ | K4: หมายเหตุ
A5: 46143 | B5: อ.เมือง จ.พิจิตร | C5: JB0326106813 | D5: 128 | E5: ราคาเหมา | F5: {=IFERROR(INDEX(ราคาขนส่ง!$D$3:$D$102,MATCH(1,IF(ราคาขนส่ง!$B$3:$B$102=$B5,IF(ราคาขนส่ง!$C$3:$C$102=$E5,1)),0)),"")} -> 1650 | G5: =IFERROR(IF(F5>10,F5,F5*D5),"") -> 1650 | I5: =IFERROR(SUM(G5+H5),"") -> 1650 | J5: =IFERROR(SUM(H5+I5),"") -> 1650
A6: 46144 | B6: อ.บึงสามพัน จ.พช | C6: JB0326106819 | D6: 339 | E6: ราคาชิ้น | F6: {=IFERROR(INDEX(ราคาขนส่ง!$D$3:$D$102,MATCH(1,IF(ราคาขนส่ง!$B$3:$B$102=$B6,IF(ราคาขนส่ง!$C$3:$C$102=$E6,1)),0)),"")} -> 7.8 | G6: =IFERROR(IF(F6>10,F6,F6*D6),"") -> 2644.2 | I6: =IFERROR(SUM(G6+H6),"") -> 2644.2 | J6: =IFERROR(SUM(H6+I6),"") -> 2644.2
